Workbook
Name AvgSalary: Inputs!$B$20
Name BaseRevenue: Inputs!$B$7
Name COGS_Pct: Inputs!$B$12
Name DeprStream: Depreciation_Sched!$B$41:$AK$41
Name DPO: Inputs!$B$25
Name DSI: Inputs!$B$24
Name DSO: Inputs!$B$23
Name FixedOpEx: Inputs!$B$13
Name HC_Start: Inputs!$B$18
Name HiringRate: Inputs!$B$19
Name InitCash: Inputs!$B$29
Name OpExVarPct: Inputs!$B$14
Name PriceGrowth: Inputs!$B$9
Name Scenario_Table: Scenario_Table!$A$2:$F$4
Name ScenarioSelector: Inputs!$B$4
Name Seasonality: Inputs!$A$33:$L$33
Name TaxRate: Inputs!$B$15
Name UsefulLife: Inputs!$B$28
Name VolGrowth: Inputs!$B$8

Sheet Inputs
A1: P3 FP&A Model Inputs
A3: SCENARIO CONTROL | B3: Value | C3: Named Range
A4: Active Scenario | B4: Base | C4: ScenarioSelector
A6: REVENUE DRIVERS | B6: Value | C6: Named Range
A7: Base Monthly Revenue | B7: 150000 | C7: BaseRevenue
A8: Volume Growth (mo) | B8: 0.02 | C8: VolGrowth
A9: Price Growth (mo) | B9: 0.005 | C9: PriceGrowth
A11: COST DRIVERS | B11: Value | C11: Named Range
A12: COGS % of Rev | B12: 0.4 | C12: COGS_Pct
A13: Fixed OpEx (Monthly) | B13: 45000 | C13: FixedOpEx
A14: OpEx Variable % | B14: 0.1 | C14: OpExVarPct
A15: Tax Rate | B15: 0.25 | C15: TaxRate
A17: HEADCOUNT DRIVERS | B17: Value | C17: Named Range
A18: Start Headcount | B18: 12 | C18: HC_Start
A19: Hiring Rate (mo) | B19: 0.2 | C19: HiringRate
A20: Avg Salary | B20: 6000 | C20: AvgSalary
A22: WORKING CAPITAL DRIVERS | B22: Value | C22: Named Range
A23: DSO (Days Sales Outstanding) | B23: 45 | C23: DSO
A24: DSI (Days Sales Inventory) | B24: 30 | C24: DSI
A25: DPO (Days Payable Outstanding) | B25: 30 | C25: DPO
A27: ASSETS & FUNDING | B27: Value | C27: Named Range
A28: Useful Life (Months) | B28: 60 | C28: UsefulLife
A29: Initial Cash | B29: 500000 | C29: InitCash
A31: SEASONALITY PROFILE
A32: 1 | B32: 2 | C32: 3 | D32: 4 | E32: 5 | F32: 6 | G32: 7 | H32: 8 | I32: 9 | J32: 10 | K32: 11 | L32: 12
A33: 0.85 | B33: 0.85 | C33: 0.9 | D33: 0.95 | E33: 1 | F33: 1.05 | G33: 1.1 | H33: 1.05 | I33: 1.1 | J33: 1.15 | K33: 1.2 | L33: 1.4

Sheet Scenario_Table
A1: Scenario | B1: Revenue_Mult | C1: COGS_Mult | D1: Vol_Adj | E1: Price_Adj | F1: CapEx_Mult
A2: Base | B2: 1 | C2: 1 | D2: 0 | E2: 0 | F2: 1
A3: Best | B3: 1.15 | C3: 0.95 | D3: 0.01 | E3: 0.005 | F3: 1.2
A4: Worst | B4: 0.85 | C4: 1.1 | D4: -0.01 | E4: -0.005 | F4: 0.8

Sheet Depreciation_Sched
A1: Date | B1: Jan-25 | C1: Feb-25 | D1: Mar-25 | E1: Apr-25 | F1: May-25 | G1: Jun-25 | H1: Jul-25 | I1: Aug-25 | J1: Sep-25 | K1: Oct-25 | L1: Nov-25 | M1: Dec-25 | N1: Jan-26 | O1: Feb-26 | P1: Mar-26 | Q1: Apr-26 | R1: May-26 | S1: Jun-26 | T1: Jul-26 | U1: Aug-26 | V1: Sep-26 | W1: Oct-26 | X1: Nov-26 | Y1: Dec-26 | Z1: Jan-27 | AA1: Feb-27 | AB1: Mar-27 | AC1: Apr-27 | AD1: May-27 | AE1: Jun-27 | AF1: Jul-27 | AG1: Aug-27 | AH1: Sep-27 | AI1: Oct-27 | AJ1: Nov-27 | AK1: Dec-27
A2: New Capex | B2: =Engine!B9 -> 0 | C2: =Engine!C9 -> 0 | D2: =Engine!D9 -> 0 | E2: =Engine!E9 -> 0 | F2: =Engine!F9 -> 0 | G2: =Engine!G9 -> 0 | H2: =Engine!H9 -> 0 | I2: =Engine!I9 -> 0 | ... AK2: =Engine!AK9 -> 0
A3: Depreciation Waterfall
A4: Batch Jan-25 | B4: =IF(AND(0>=0, 0<0+UsefulLife), B2/UsefulLife, 0) -> 0 | C4: =IF(AND(1>=0, 1<0+UsefulLife), B2/UsefulLife, 0) -> 0 | D4: =IF(AND(2>=0, 2<0+UsefulLife), B2/UsefulLife, 0) -> 0 | E4: =IF(AND(3>=0, 3<0+UsefulLife), B2/UsefulLife, 0) -> 0 | F4: =IF(AND(4>=0, 4<0+UsefulLife), B2/UsefulLife, 0) -> 0 | G4: =IF(AND(5>=0, 5<0+UsefulLife), B2/UsefulLife, 0) -> 0 | H4: =IF(AND(6>=0, 6<0+UsefulLife), B2/UsefulLife, 0) -> 0 | I4: =IF(AND(7>=0, 7<0+UsefulLife), B2/UsefulLife, 0) -> 0 | J4: =IF(AND(8>=0, 8<0+UsefulLife), B2/UsefulLife, 0) -> 0 | K4: =IF(AND(9>=0, 9<0+UsefulLife), B2/UsefulLife, 0) -> 0 | L4: =IF(AND(10>=0, 10<0+UsefulLife), B2/UsefulLife, 0) -> 0 | M4: =IF(AND(11>=0, 11<0+UsefulLife), B2/UsefulLife, 0) -> 0 | N4: =IF(AND(12>=0, 12<0+UsefulLife), B2/UsefulLife, 0) -> 0 | O4: =IF(AND(13>=0, 13<0+UsefulLife), B2/UsefulLife, 0) -> 0 | P4: =IF(AND(14>=0, 14<0+UsefulLife), B2/UsefulLife, 0) -> 0 | Q4: =IF(AND(15>=0, 15<0+UsefulLife), B2/UsefulLife, 0) -> 0 | R4: =IF(AND(16>=0, 16<0+UsefulLife), B2/UsefulLife, 0) -> 0 | S4: =IF(AND(17>=0, 17<0+UsefulLife), B2/UsefulLife, 0) -> 0 | T4: =IF(AND(18>=0, 18<0+UsefulLife), B2/UsefulLife, 0) -> 0 | U4: =IF(AND(19>=0, 19<0+UsefulLife), B2/UsefulLife, 0) -> 0 | V4: =IF(AND(20>=0, 20<0+UsefulLife), B2/UsefulLife, 0) -> 0 | W4: =IF(AND(21>=0, 21<0+UsefulLife), B2/UsefulLife, 0) -> 0 | X4: =IF(AND(22>=0, 22<0+UsefulLife), B2/UsefulLife, 0) -> 0 | Y4: =IF(AND(23>=0, 23<0+UsefulLife), B2/UsefulLife, 0) -> 0 | Z4: =IF(AND(24>=0, 24<0+UsefulLife), B2/UsefulLife, 0) -> 0 | AA4: =IF(AND(25>=0, 25<0+UsefulLife), B2/UsefulLife, 0) -> 0 | AB4: =IF(AND(26>=0, 26<0+UsefulLife), B2/UsefulLife, 0) -> 0 | AC4: =IF(AND(27>=0, 27<0+UsefulLife), B2/UsefulLife, 0) -> 0 | AD4: =IF(AND(28>=0, 28<0+UsefulLife), B2/UsefulLife, 0) -> 0 | AE4: =IF(AND(29>=0, 29<0+UsefulLife), B2/UsefulLife, 0) -> 0 | AF4: =IF(AND(30>=0, 30<0+UsefulLife), B2/UsefulLife, 0) -> 0 | AG4: =IF(AND(31>=0, 31<0+UsefulLife), B2/UsefulLife, 0) -> 0 | AH4: =IF(AND(32>=0, 32<0+UsefulLife), B2/UsefulLife, 0) -> 0 | AI4: =IF(AND(33>=0, 33<0+UsefulLife), B2/UsefulLife, 0) -> 0 | AJ4: =IF(AND(34>=0, 34<0+UsefulLife), B2/UsefulLife, 0) -> 0 | AK4: =IF(AND(35>=0, 35<0+UsefulLife), B2/UsefulLife, 0) -> 0
A5: Batch Feb-25 | B5: =IF(AND(0>=1, 0<1+UsefulLife), C2/UsefulLife, 0) -> 0 | C5: =IF(AND(1>=1, 1<1+UsefulLife), C2/UsefulLife, 0) -> 0 | D5: =IF(AND(2>=1, 2<1+UsefulLife), C2/UsefulLife, 0) -> 0 | E5: =IF(AND(3>=1, 3<1+UsefulLife), C2/UsefulLife, 0) -> 0 | F5: =IF(AND(4>=1, 4<1+UsefulLife), C2/UsefulLife, 0) -> 0 | G5: =IF(AND(5>=1, 5<1+UsefulLife), C2/UsefulLife, 0) -> 0 | H5: =IF(AND(6>=1, 6<1+UsefulLife), C2/UsefulLife, 0) -> 0 | I5: =IF(AND(7>=1, 7<1+UsefulLife), C2/UsefulLife, 0) -> 0 | J5: =IF(AND(8>=1, 8<1+UsefulLife), C2/UsefulLife, 0) -> 0 | K5: =IF(AND(9>=1, 9<1+UsefulLife), C2/UsefulLife, 0) -> 0 | L5: =IF(AND(10>=1, 10<1+UsefulLife), C2/UsefulLife, 0) -> 0 | M5: =IF(AND(11>=1, 11<1+UsefulLife), C2/UsefulLife, 0) -> 0 | N5: =IF(AND(12>=1, 12<1+UsefulLife), C2/UsefulLife, 0) -> 0 | O5: =IF(AND(13>=1, 13<1+UsefulLife), C2/UsefulLife, 0) -> 0 | P5: =IF(AND(14>=1, 14<1+UsefulLife), C2/UsefulLife, 0) -> 0 | Q5: =IF(AND(15>=1, 15<1+UsefulLife), C2/UsefulLife, 0) -> 0 | R5: =IF(AND(16>=1, 16<1+UsefulLife), C2/UsefulLife, 0) -> 0 | S5: =IF(AND(17>=1, 17<1+UsefulLife), C2/UsefulLife, 0) -> 0 | T5: =IF(AND(18>=1, 18<1+UsefulLife), C2/UsefulLife, 0) -> 0 | U5: =IF(AND(19>=1, 19<1+UsefulLife), C2/UsefulLife, 0) -> 0 | V5: =IF(AND(20>=1, 20<1+UsefulLife), C2/UsefulLife, 0) -> 0 | W5: =IF(AND(21>=1, 21<1+UsefulLife), C2/UsefulLife, 0) -> 0 | X5: =IF(AND(22>=1, 22<1+UsefulLife), C2/UsefulLife, 0) -> 0 | Y5: =IF(AND(23>=1, 23<1+UsefulLife), C2/UsefulLife, 0) -> 0 | Z5: =IF(AND(24>=1, 24<1+UsefulLife), C2/UsefulLife, 0) -> 0 | AA5: =IF(AND(25>=1, 25<1+UsefulLife), C2/UsefulLife, 0) -> 0 | AB5: =IF(AND(26>=1, 26<1+UsefulLife), C2/UsefulLife, 0) -> 0 | AC5: =IF(AND(27>=1, 27<1+UsefulLife), C2/UsefulLife, 0) -> 0 | AD5: =IF(AND(28>=1, 28<1+UsefulLife), C2/UsefulLife, 0) -> 0 | AE5: =IF(AND(29>=1, 29<1+UsefulLife), C2/UsefulLife, 0) -> 0 | AF5: =IF(AND(30>=1, 30<1+UsefulLife), C2/UsefulLife, 0) -> 0 | AG5: =IF(AND(31>=1, 31<1+UsefulLife), C2/UsefulLife, 0) -> 0 | AH5: =IF(AND(32>=1, 32<1+UsefulLife), C2/UsefulLife, 0) -> 0 | AI5: =IF(AND(33>=1, 33<1+UsefulLife), C2/UsefulLife, 0) -> 0 | AJ5: =IF(AND(34>=1, 34<1+UsefulLife), C2/UsefulLife, 0) -> 0 | AK5: =IF(AND(35>=1, 35<1+UsefulLife), C2/UsefulLife, 0) -> 0
A6: Batch Mar-25 | B6: =IF(AND(0>=2, 0<2+UsefulLife), D2/UsefulLife, 0) -> 0 | C6: =IF(AND(1>=2, 1<2+UsefulLife), D2/UsefulLife, 0) -> 0 | D6: =IF(AND(2>=2, 2<2+UsefulLife), D2/UsefulLife, 0) -> 0 | E6: =IF(AND(3>=2, 3<2+UsefulLife), D2/UsefulLife, 0) -> 0 | F6: =IF(AND(4>=2, 4<2+UsefulLife), D2/UsefulLife, 0) -> 0 | G6: =IF(AND(5>=2, 5<2+UsefulLife), D2/UsefulLife, 0) -> 0 | H6: =IF(AND(6>=2, 6<2+UsefulLife), D2/UsefulLife, 0) -> 0 | I6: =IF(AND(7>=2, 7<2+UsefulLife), D2/UsefulLife, 0) -> 0 | J6: =IF(AND(8>=2, 8<2+UsefulLife), D2/UsefulLife, 0) -> 0 | K6: =IF(AND(9>=2, 9<2+UsefulLife), D2/UsefulLife, 0) -> 0 | L6: =IF(AND(10>=2, 10<2+UsefulLife), D2/UsefulLife, 0) -> 0 | M6: =IF(AND(11>=2, 11<2+UsefulLife), D2/UsefulLife, 0) -> 0 | N6: =IF(AND(12>=2, 12<2+UsefulLife), D2/UsefulLife, 0) -> 0 | O6: =IF(AND(13>=2, 13<2+UsefulLife), D2/UsefulLife, 0) -> 0 | P6: =IF(AND(14>=2, 14<2+UsefulLife), D2/UsefulLife, 0) -> 0 | Q6: =IF(AND(15>=2, 15<2+UsefulLife), D2/UsefulLife, 0) -> 0 | R6: =IF(AND(16>=2, 16<2+UsefulLife), D2/UsefulLife, 0) -> 0 | S6: =IF(AND(17>=2, 17<2+UsefulLife), D2/UsefulLife, 0) -> 0 | T6: =IF(AND(18>=2, 18<2+UsefulLife), D2/UsefulLife, 0) -> 0 | U6: =IF(AND(19>=2, 19<2+UsefulLife), D2/UsefulLife, 0) -> 0 | V6: =IF(AND(20>=2, 20<2+UsefulLife), D2/UsefulLife, 0) -> 0 | W6: =IF(AND(21>=2, 21<2+UsefulLife), D2/UsefulLife, 0) -> 0 | X6: =IF(AND(22>=2, 22<2+UsefulLife), D2/UsefulLife, 0) -> 0 | Y6: =IF(AND(23>=2, 23<2+UsefulLife), D2/UsefulLife, 0) -> 0 | Z6: =IF(AND(24>=2, 24<2+UsefulLife), D2/UsefulLife, 0) -> 0 | AA6: =IF(AND(25>=2, 25<2+UsefulLife), D2/UsefulLife, 0) -> 0 | AB6: =IF(AND(26>=2, 26<2+UsefulLife), D2/UsefulLife, 0) -> 0 | AC6: =IF(AND(27>=2, 27<2+UsefulLife), D2/UsefulLife, 0) -> 0 | AD6: =IF(AND(28>=2, 28<2+UsefulLife), D2/UsefulLife, 0) -> 0 | AE6: =IF(AND(29>=2, 29<2+UsefulLife), D2/UsefulLife, 0) -> 0 | AF6: =IF(AND(30>=2, 30<2+UsefulLife), D2/UsefulLife, 0) -> 0 | AG6: =IF(AND(31>=2, 31<2+UsefulLife), D2/UsefulLife, 0) -> 0 | AH6: =IF(AND(32>=2, 32<2+UsefulLife), D2/UsefulLife, 0) -> 0 | AI6: =IF(AND(33>=2, 33<2+UsefulLife), D2/UsefulLife, 0) -> 0 | AJ6: =IF(AND(34>=2, 34<2+UsefulLife), D2/UsefulLife, 0) -> 0 | AK6: =IF(AND(35>=2, 35<2+UsefulLife), D2/UsefulLife, 0) -> 0
A7: Batch Apr-25 | B7: =IF(AND(0>=3, 0<3+UsefulLife), E2/UsefulLife, 0) -> 0 | C7: =IF(AND(1>=3, 1<3+UsefulLife), E2/UsefulLife, 0) -> 0 | D7: =IF(AND(2>=3, 2<3+UsefulLife), E2/UsefulLife, 0) -> 0 | E7: =IF(AND(3>=3, 3<3+UsefulLife), E2/UsefulLife, 0) -> 0 | F7: =IF(AND(4>=3, 4<3+UsefulLife), E2/UsefulLife, 0) -> 0 | G7: =IF(AND(5>=3, 5<3+UsefulLife), E2/UsefulLife, 0) -> 0 | H7: =IF(AND(6>=3, 6<3+UsefulLife), E2/UsefulLife, 0) -> 0 | I7: =IF(AND(7>=3, 7<3+UsefulLife), E2/UsefulLife, 0) -> 0 | J7: =IF(AND(8>=3, 8<3+UsefulLife), E2/UsefulLife, 0) -> 0 | K7: =IF(AND(9>=3, 9<3+UsefulLife), E2/UsefulLife, 0) -> 0 | L7: =IF(AND(10>=3, 10<3+UsefulLife), E2/UsefulLife, 0) -> 0 | M7: =IF(AND(11>=3, 11<3+UsefulLife), E2/UsefulLife, 0) -> 0 | N7: =IF(AND(12>=3, 12<3+UsefulLife), E2/UsefulLife, 0) -> 0 | O7: =IF(AND(13>=3, 13<3+UsefulLife), E2/UsefulLife, 0) -> 0 | P7: =IF(AND(14>=3, 14<3+UsefulLife), E2/UsefulLife, 0) -> 0 | Q7: =IF(AND(15>=3, 15<3+UsefulLife), E2/UsefulLife, 0) -> 0 | R7: =IF(AND(16>=3, 16<3+UsefulLife), E2/UsefulLife, 0) -> 0 | S7: =IF(AND(17>=3, 17<3+UsefulLife), E2/UsefulLife, 0) -> 0 | T7: =IF(AND(18>=3, 18<3+UsefulLife), E2/UsefulLife, 0) -> 0 | U7: =IF(AND(19>=3, 19<3+UsefulLife), E2/UsefulLife, 0) -> 0 | V7: =IF(AND(20>=3, 20<3+UsefulLife), E2/UsefulLife, 0) -> 0 | W7: =IF(AND(21>=3, 21<3+UsefulLife), E2/UsefulLife, 0) -> 0 | X7: =IF(AND(22>=3, 22<3+UsefulLife), E2/UsefulLife, 0) -> 0 | Y7: =IF(AND(23>=3, 23<3+UsefulLife), E2/UsefulLife, 0) -> 0 | Z7: =IF(AND(24>=3, 24<3+UsefulLife), E2/UsefulLife, 0) -> 0 | AA7: =IF(AND(25>=3, 25<3+UsefulLife), E2/UsefulLife, 0) -> 0 | AB7: =IF(AND(26>=3, 26<3+UsefulLife), E2/UsefulLife, 0) -> 0 | AC7: =IF(AND(27>=3, 27<3+UsefulLife), E2/UsefulLife, 0) -> 0 | AD7: =IF(AND(28>=3, 28<3+UsefulLife), E2/UsefulLife, 0) -> 0 | AE7: =IF(AND(29>=3, 29<3+UsefulLife), E2/UsefulLife, 0) -> 0 | AF7: =IF(AND(30>=3, 30<3+UsefulLife), E2/UsefulLife, 0) -> 0 | AG7: =IF(AND(31>=3, 31<3+UsefulLife), E2/UsefulLife, 0) -> 0 | AH7: =IF(AND(32>=3, 32<3+UsefulLife), E2/UsefulLife, 0) -> 0 | AI7: =IF(AND(33>=3, 33<3+UsefulLife), E2/UsefulLife, 0) -> 0 | AJ7: =IF(AND(34>=3, 34<3+UsefulLife), E2/UsefulLife, 0) -> 0 | AK7: =IF(AND(35>=3, 35<3+UsefulLife), E2/UsefulLife, 0) -> 0
A8: Batch May-25 | B8: =IF(AND(0>=4, 0<4+UsefulLife), F2/UsefulLife, 0) -> 0 | C8: =IF(AND(1>=4, 1<4+UsefulLife), F2/UsefulLife, 0) -> 0 | D8: =IF(AND(2>=4, 2<4+UsefulLife), F2/UsefulLife, 0) -> 0 | E8: =IF(AND(3>=4, 3<4+UsefulLife), F2/UsefulLife, 0) -> 0 | F8: =IF(AND(4>=4, 4<4+UsefulLife), F2/UsefulLife, 0) -> 0 | G8: =IF(AND(5>=4, 5<4+UsefulLife), F2/UsefulLife, 0) -> 0 | H8: =IF(AND(6>=4, 6<4+UsefulLife), F2/UsefulLife, 0) -> 0 | I8: =IF(AND(7>=4, 7<4+UsefulLife), F2/UsefulLife, 0) -> 0 | J8: =IF(AND(8>=4, 8<4+UsefulLife), F2/UsefulLife, 0) -> 0 | K8: =IF(AND(9>=4, 9<4+UsefulLife), F2/UsefulLife, 0) -> 0 | L8: =IF(AND(10>=4, 10<4+UsefulLife), F2/UsefulLife, 0) -> 0 | M8: =IF(AND(11>=4, 11<4+UsefulLife), F2/UsefulLife, 0) -> 0 | N8: =IF(AND(12>=4, 12<4+UsefulLife), F2/UsefulLife, 0) -> 0 | O8: =IF(AND(13>=4, 13<4+UsefulLife), F2/UsefulLife, 0) -> 0 | P8: =IF(AND(14>=4, 14<4+UsefulLife), F2/UsefulLife, 0) -> 0 | Q8: =IF(AND(15>=4, 15<4+UsefulLife), F2/UsefulLife, 0) -> 0 | R8: =IF(AND(16>=4, 16<4+UsefulLife), F2/UsefulLife, 0) -> 0 | S8: =IF(AND(17>=4, 17<4+UsefulLife), F2/UsefulLife, 0) -> 0 | T8: =IF(AND(18>=4, 18<4+UsefulLife), F2/UsefulLife, 0) -> 0 | U8: =IF(AND(19>=4, 19<4+UsefulLife), F2/UsefulLife, 0) -> 0 | V8: =IF(AND(20>=4, 20<4+UsefulLife), F2/UsefulLife, 0) -> 0 | W8: =IF(AND(21>=4, 21<4+UsefulLife), F2/UsefulLife, 0) -> 0 | X8: =IF(AND(22>=4, 22<4+UsefulLife), F2/UsefulLife, 0) -> 0 | Y8: =IF(AND(23>=4, 23<4+UsefulLife), F2/UsefulLife, 0) -> 0 | Z8: =IF(AND(24>=4, 24<4+UsefulLife), F2/UsefulLife, 0) -> 0 | AA8: =IF(AND(25>=4, 25<4+UsefulLife), F2/UsefulLife, 0) -> 0 | AB8: =IF(AND(26>=4, 26<4+UsefulLife), F2/UsefulLife, 0) -> 0 | AC8: =IF(AND(27>=4, 27<4+UsefulLife), F2/UsefulLife, 0) -> 0 | AD8: =IF(AND(28>=4, 28<4+UsefulLife), F2/UsefulLife, 0) -> 0 | AE8: =IF(AND(29>=4, 29<4+UsefulLife), F2/UsefulLife, 0) -> 0 | AF8: =IF(AND(30>=4, 30<4+UsefulLife), F2/UsefulLife, 0) -> 0 | AG8: =IF(AND(31>=4, 31<4+UsefulLife), F2/UsefulLife, 0) -> 0 | AH8: =IF(AND(32>=4, 32<4+UsefulLife), F2/UsefulLife, 0) -> 0 | AI8: =IF(AND(33>=4, 33<4+UsefulLife), F2/UsefulLife, 0) -> 0 | AJ8: =IF(AND(34>=4, 34<4+UsefulLife), F2/UsefulLife, 0) -> 0 | AK8: =IF(AND(35>=4, 35<4+UsefulLife), F2/UsefulLife, 0) -> 0
A9: Batch Jun-25 | B9: =IF(AND(0>=5, 0<5+UsefulLife), G2/UsefulLife, 0) -> 0 | C9: =IF(AND(1>=5, 1<5+UsefulLife), G2/UsefulLife, 0) -> 0 | D9: =IF(AND(2>=5, 2<5+UsefulLife), G2/UsefulLife, 0) -> 0 | E9: =IF(AND(3>=5, 3<5+UsefulLife), G2/UsefulLife, 0) -> 0 | F9: =IF(AND(4>=5, 4<5+UsefulLife), G2/UsefulLife, 0) -> 0 | G9: =IF(AND(5>=5, 5<5+UsefulLife), G2/UsefulLife, 0) -> 0 | H9: =IF(AND(6>=5, 6<5+UsefulLife), G2/UsefulLife, 0) -> 0 | I9: =IF(AND(7>=5, 7<5+UsefulLife), G2/UsefulLife, 0) -> 0 | J9: =IF(AND(8>=5, 8<5+UsefulLife), G2/UsefulLife, 0) -> 0 | K9: =IF(AND(9>=5, 9<5+UsefulLife), G2/UsefulLife, 0) -> 0 | L9: =IF(AND(10>=5, 10<5+UsefulLife), G2/UsefulLife, 0) -> 0 | M9: =IF(AND(11>=5, 11<5+UsefulLife), G2/UsefulLife, 0) -> 0 | N9: =IF(AND(12>=5, 12<5+UsefulLife), G2/UsefulLife, 0) -> 0 | O9: =IF(AND(13>=5, 13<5+UsefulLife), G2/UsefulLife, 0) -> 0 | P9: =IF(AND(14>=5, 14<5+UsefulLife), G2/UsefulLife, 0) -> 0 | Q9: =IF(AND(15>=5, 15<5+UsefulLife), G2/UsefulLife, 0) -> 0 | R9: =IF(AND(16>=5, 16<5+UsefulLife), G2/UsefulLife, 0) -> 0 | S9: =IF(AND(17>=5, 17<5+UsefulLife), G2/UsefulLife, 0) -> 0 | T9: =IF(AND(18>=5, 18<5+UsefulLife), G2/UsefulLife, 0) -> 0 | U9: =IF(AND(19>=5, 19<5+UsefulLife), G2/UsefulLife, 0) -> 0 | V9: =IF(AND(20>=5, 20<5+UsefulLife), G2/UsefulLife, 0) -> 0 | W9: =IF(AND(21>=5, 21<5+UsefulLife), G2/UsefulLife, 0) -> 0 | X9: =IF(AND(22>=5, 22<5+UsefulLife), G2/UsefulLife, 0) -> 0 | Y9: =IF(AND(23>=5, 23<5+UsefulLife), G2/UsefulLife, 0) -> 0 | Z9: =IF(AND(24>=5, 24<5+UsefulLife), G2/UsefulLife, 0) -> 0 | AA9: =IF(AND(25>=5, 25<5+UsefulLife), G2/UsefulLife, 0) -> 0 | AB9: =IF(AND(26>=5, 26<5+UsefulLife), G2/UsefulLife, 0) -> 0 | AC9: =IF(AND(27>=5, 27<5+UsefulLife), G2/UsefulLife, 0) -> 0 | AD9: =IF(AND(28>=5, 28<5+UsefulLife), G2/UsefulLife, 0) -> 0 | AE9: =IF(AND(29>=5, 29<5+UsefulLife), G2/UsefulLife, 0) -> 0 | AF9: =IF(AND(30>=5, 30<5+UsefulLife), G2/UsefulLife, 0) -> 0 | AG9: =IF(AND(31>=5, 31<5+UsefulLife), G2/UsefulLife, 0) -> 0 | AH9: =IF(AND(32>=5, 32<5+UsefulLife), G2/UsefulLife, 0) -> 0 | AI9: =IF(AND(33>=5, 33<5+UsefulLife), G2/UsefulLife, 0) -> 0 | AJ9: =IF(AND(34>=5, 34<5+UsefulLife), G2/UsefulLife, 0) -> 0 | AK9: =IF(AND(35>=5, 35<5+UsefulLife), G2/UsefulLife, 0) -> 0
A10: Batch Jul-25 | B10: =IF(AND(0>=6, 0<6+UsefulLife), H2/UsefulLife, 0) -> 0 | C10: =IF(AND(1>=6, 1<6+UsefulLife), H2/UsefulLife, 0) -> 0 | D10: =IF(AND(2>=6, 2<6+UsefulLife), H2/UsefulLife, 0) -> 0 | E10: =IF(AND(3>=6, 3<6+UsefulLife), H2/UsefulLife, 0) -> 0 | F10: =IF(AND(4>=6, 4<6+UsefulLife), H2/UsefulLife, 0) -> 0 | G10: =IF(AND(5>=6, 5<6+UsefulLife), H2/UsefulLife, 0) -> 0 | H10: =IF(AND(6>=6, 6<6+UsefulLife), H2/UsefulLife, 0) -> 0 | I10: =IF(AND(7>=6, 7<6+UsefulLife), H2/UsefulLife, 0) -> 0 | J10: =IF(AND(8>=6, 8<6+UsefulLife), H2/UsefulLife, 0) -> 0 | K10: =IF(AND(9>=6, 9<6+UsefulLife), H2/UsefulLife, 0) -> 0 | L10: =IF(AND(10>=6, 10<6+UsefulLife), H2/UsefulLife, 0) -> 0 | M10: =IF(AND(11>=6, 11<6+UsefulLife), H2/UsefulLife, 0) -> 0 | N10: =IF(AND(12>=6, 12<6+UsefulLife), H2/UsefulLife, 0) -> 0 | O10: =IF(AND(13>=6, 13<6+UsefulLife), H2/UsefulLife, 0) -> 0 | P10: =IF(AND(14>=6, 14<6+UsefulLife), H2/UsefulLife, 0) -> 0 | Q10: =IF(AND(15>=6, 15<6+UsefulLife), H2/UsefulLife, 0) -> 0 | R10: =IF(AND(16>=6, 16<6+UsefulLife), H2/UsefulLife, 0) -> 0 | S10: =IF(AND(17>=6, 17<6+UsefulLife), H2/UsefulLife, 0) -> 0 | T10: =IF(AND(18>=6, 18<6+UsefulLife), H2/UsefulLife, 0) -> 0 | U10: =IF(AND(19>=6, 19<6+UsefulLife), H2/UsefulLife, 0) -> 0 | V10: =IF(AND(20>=6, 20<6+UsefulLife), H2/UsefulLife, 0) -> 0 | W10: =IF(AND(21>=6, 21<6+UsefulLife), H2/UsefulLife, 0) -> 0 | X10: =IF(AND(22>=6, 22<6+UsefulLife), H2/UsefulLife, 0) -> 0 | Y10: =IF(AND(23>=6, 23<6+UsefulLife), H2/UsefulLife, 0) -> 0 | Z10: =IF(AND(24>=6, 24<6+UsefulLife), H2/UsefulLife, 0) -> 0 | AA10: =IF(AND(25>=6, 25<6+UsefulLife), H2/UsefulLife, 0) -> 0 | AB10: =IF(AND(26>=6, 26<6+UsefulLife), H2/UsefulLife, 0) -> 0 | AC10: =IF(AND(27>=6, 27<6+UsefulLife), H2/UsefulLife, 0) -> 0 | AD10: =IF(AND(28>=6, 28<6+UsefulLife), H2/UsefulLife, 0) -> 0 | AE10: =IF(AND(29>=6, 29<6+UsefulLife), H2/UsefulLife, 0) -> 0 | AF10: =IF(AND(30>=6, 30<6+UsefulLife), H2/UsefulLife, 0) -> 0 | AG10: =IF(AND(31>=6, 31<6+UsefulLife), H2/UsefulLife, 0) -> 0 | AH10: =IF(AND(32>=6, 32<6+UsefulLife), H2/UsefulLife, 0) -> 0 | AI10: =IF(AND(33>=6, 33<6+UsefulLife), H2/UsefulLife, 0) -> 0 | AJ10: =IF(AND(34>=6, 34<6+UsefulLife), H2/UsefulLife, 0) -> 0 | AK10: =IF(AND(35>=6, 35<6+UsefulLife), H2/UsefulLife, 0) -> 0
A11: Batch Aug-25 | B11: =IF(AND(0>=7, 0<7+UsefulLife), I2/UsefulLife, 0) -> 0 | C11: =IF(AND(1>=7, 1<7+UsefulLife), I2/UsefulLife, 0) -> 0 | D11: =IF(AND(2>=7, 2<7+UsefulLife), I2/UsefulLife, 0) -> 0 | E11: =IF(AND(3>=7, 3<7+UsefulLife), I2/UsefulLife, 0) -> 0 | F11: =IF(AND(4>=7, 4<7+UsefulLife), I2/UsefulLife, 0) -> 0 | G11: =IF(AND(5>=7, 5<7+UsefulLife), I2/UsefulLife, 0) -> 0 | H11: =IF(AND(6>=7, 6<7+UsefulLife), I2/UsefulLife, 0) -> 0 | I11: =IF(AND(7>=7, 7<7+UsefulLife), I2/UsefulLife, 0) -> 0 | J11: =IF(AND(8>=7, 8<7+UsefulLife), I2/UsefulLife, 0) -> 0 | K11: =IF(AND(9>=7, 9<7+UsefulLife), I2/UsefulLife, 0) -> 0 | L11: =IF(AND(10>=7, 10<7+UsefulLife), I2/UsefulLife, 0) -> 0 | M11: =IF(AND(11>=7, 11<7+UsefulLife), I2/UsefulLife, 0) -> 0 | N11: =IF(AND(12>=7, 12<7+UsefulLife), I2/UsefulLife, 0) -> 0 | O11: =IF(AND(13>=7, 13<7+UsefulLife), I2/UsefulLife, 0) -> 0 | P11: =IF(AND(14>=7, 14<7+UsefulLife), I2/UsefulLife, 0) -> 0 | Q11: =IF(AND(15>=7, 15<7+UsefulLife), I2/UsefulLife, 0) -> 0 | R11: =IF(AND(16>=7, 16<7+UsefulLife), I2/UsefulLife, 0) -> 0 | S11: =IF(AND(17>=7, 17<7+UsefulLife), I2/UsefulLife, 0) -> 0 | T11: =IF(AND(18>=7, 18<7+UsefulLife), I2/UsefulLife, 0) -> 0 | U11: =IF(AND(19>=7, 19<7+UsefulLife), I2/UsefulLife, 0) -> 0 | V11: =IF(AND(20>=7, 20<7+UsefulLife), I2/UsefulLife, 0) -> 0 | W11: =IF(AND(21>=7, 21<7+UsefulLife), I2/UsefulLife, 0) -> 0 | X11: =IF(AND(22>=7, 22<7+UsefulLife), I2/UsefulLife, 0) -> 0 | Y11: =IF(AND(23>=7, 23<7+UsefulLife), I2/UsefulLife, 0) -> 0 | Z11: =IF(AND(24>=7, 24<7+UsefulLife), I2/UsefulLife, 0) -> 0 | AA11: =IF(AND(25>=7, 25<7+UsefulLife), I2/UsefulLife, 0) -> 0 | AB11: =IF(AND(26>=7, 26<7+UsefulLife), I2/UsefulLife, 0) -> 0 | AC11: =IF(AND(27>=7, 27<7+UsefulLife), I2/UsefulLife, 0) -> 0 | AD11: =IF(AND(28>=7, 28<7+UsefulLife), I2/UsefulLife, 0) -> 0 | AE11: =IF(AND(29>=7, 29<7+UsefulLife), I2/UsefulLife, 0) -> 0 | AF11: =IF(AND(30>=7, 30<7+UsefulLife), I2/UsefulLife, 0) -> 0 | AG11: =IF(AND(31>=7, 31<7+UsefulLife), I2/UsefulLife, 0) -> 0 | AH11: =IF(AND(32>=7, 32<7+UsefulLife), I2/UsefulLife, 0) -> 0 | AI11: =IF(AND(33>=7, 33<7+UsefulLife), I2/UsefulLife, 0) -> 0 | AJ11: =IF(AND(34>=7, 34<7+UsefulLife), I2/UsefulLife, 0) -> 0 | AK11: =IF(AND(35>=7, 35<7+UsefulLife), I2/UsefulLife, 0) -> 0
A12: Batch Sep-25 | B12: =IF(AND(0>=8, 0<8+UsefulLife), J2/UsefulLife, 0) -> 0 | C12: =IF(AND(1>=8, 1<8+UsefulLife), J2/UsefulLife, 0) -> 0 | D12: =IF(AND(2>=8, 2<8+UsefulLife), J2/UsefulLife, 0) -> 0 | E12: =IF(AND(3>=8, 3<8+UsefulLife), J2/UsefulLife, 0) -> 0 | F12: =IF(AND(4>=8, 4<8+UsefulLife), J2/UsefulLife, 0) -> 0 | G12: =IF(AND(5>=8, 5<8+UsefulLife), J2/UsefulLife, 0) -> 0 | H12: =IF(AND(6>=8, 6<8+UsefulLife), J2/UsefulLife, 0) -> 0 | I12: =IF(AND(7>=8, 7<8+UsefulLife), J2/UsefulLife, 0) -> 0 | J12: =IF(AND(8>=8, 8<8+UsefulLife), J2/UsefulLife, 0) -> 0 | K12: =IF(AND(9>=8, 9<8+UsefulLife), J2/UsefulLife, 0) -> 0 | L12: =IF(AND(10>=8, 10<8+UsefulLife), J2/UsefulLife, 0) -> 0 | M12: =IF(AND(11>=8, 11<8+UsefulLife), J2/UsefulLife, 0) -> 0 | N12: =IF(AND(12>=8, 12<8+UsefulLife), J2/UsefulLife, 0) -> 0 | O12: =IF(AND(13>=8, 13<8+UsefulLife), J2/UsefulLife, 0) -> 0 | P12: =IF(AND(14>=8, 14<8+UsefulLife), J2/UsefulLife, 0) -> 0 | Q12: =IF(AND(15>=8, 15<8+UsefulLife), J2/UsefulLife, 0) -> 0 | R12: =IF(AND(16>=8, 16<8+UsefulLife), J2/UsefulLife, 0) -> 0 | S12: =IF(AND(17>=8, 17<8+UsefulLife), J2/UsefulLife, 0) -> 0 | T12: =IF(AND(18>=8, 18<8+UsefulLife), J2/UsefulLife, 0) -> 0 | U12: =IF(AND(19>=8, 19<8+UsefulLife), J2/UsefulLife, 0) -> 0 | V12: =IF(AND(20>=8, 20<8+UsefulLife), J2/UsefulLife, 0) -> 0 | W12: =IF(AND(21>=8, 21<8+UsefulLife), J2/UsefulLife, 0) -> 0 | X12: =IF(AND(22>=8, 22<8+UsefulLife), J2/UsefulLife, 0) -> 0 | Y12: =IF(AND(23>=8, 23<8+UsefulLife), J2/UsefulLife, 0) -> 0 | Z12: =IF(AND(24>=8, 24<8+UsefulLife), J2/UsefulLife, 0) -> 0 | AA12: =IF(AND(25>=8, 25<8+UsefulLife), J2/UsefulLife, 0) -> 0 | AB12: =IF(AND(26>=8, 26<8+UsefulLife), J2/UsefulLife, 0) -> 0 | AC12: =IF(AND(27>=8, 27<8+UsefulLife), J2/UsefulLife, 0) -> 0 | AD12: =IF(AND(28>=8, 28<8+UsefulLife), J2/UsefulLife, 0) -> 0 | AE12: =IF(AND(29>=8, 29<8+UsefulLife), J2/UsefulLife, 0) -> 0 | AF12: =IF(AND(30>=8, 30<8+UsefulLife), J2/UsefulLife, 0) -> 0 | AG12: =IF(AND(31>=8, 31<8+UsefulLife), J2/UsefulLife, 0) -> 0 | AH12: =IF(AND(32>=8, 32<8+UsefulLife), J2/UsefulLife, 0) -> 0 | AI12: =IF(AND(33>=8, 33<8+UsefulLife), J2/UsefulLife, 0) -> 0 | AJ12: =IF(AND(34>=8, 34<8+UsefulLife), J2/UsefulLife, 0) -> 0 | AK12: =IF(AND(35>=8, 35<8+UsefulLife), J2/UsefulLife, 0) -> 0
A13: Batch Oct-25 | B13: =IF(AND(0>=9, 0<9+UsefulLife), K2/UsefulLife, 0) -> 0 | C13: =IF(AND(1>=9, 1<9+UsefulLife), K2/UsefulLife, 0) -> 0 | D13: =IF(AND(2>=9, 2<9+UsefulLife), K2/UsefulLife, 0) -> 0 | E13: =IF(AND(3>=9, 3<9+UsefulLife), K2/UsefulLife, 0) -> 0 | F13: =IF(AND(4>=9, 4<9+UsefulLife), K2/UsefulLife, 0) -> 0 | G13: =IF(AND(5>=9, 5<9+UsefulLife), K2/UsefulLife, 0) -> 0 | H13: =IF(AND(6>=9, 6<9+UsefulLife), K2/UsefulLife, 0) -> 0 | I13: =IF(AND(7>=9, 7<9+UsefulLife), K2/UsefulLife, 0) -> 0 | J13: =IF(AND(8>=9, 8<9+UsefulLife), K2/UsefulLife, 0) -> 0 | K13: =IF(AND(9>=9, 9<9+UsefulLife), K2/UsefulLife, 0) -> 0 | L13: =IF(AND(10>=9, 10<9+UsefulLife), K2/UsefulLife, 0) -> 0 | M13: =IF(AND(11>=9, 11<9+UsefulLife), K2/UsefulLife, 0) -> 0 | N13: =IF(AND(12>=9, 12<9+UsefulLife), K2/UsefulLife, 0) -> 0 | O13: =IF(AND(13>=9, 13<9+UsefulLife), K2/UsefulLife, 0) -> 0 | P13: =IF(AND(14>=9, 14<9+UsefulLife), K2/UsefulLife, 0) -> 0 | Q13: =IF(AND(15>=9, 15<9+UsefulLife), K2/UsefulLife, 0) -> 0 | R13: =IF(AND(16>=9, 16<9+UsefulLife), K2/UsefulLife, 0) -> 0 | S13: =IF(AND(17>=9, 17<9+UsefulLife), K2/UsefulLife, 0) -> 0 | T13: =IF(AND(18>=9, 18<9+UsefulLife), K2/UsefulLife, 0) -> 0 | U13: =IF(AND(19>=9, 19<9+UsefulLife), K2/UsefulLife, 0) -> 0 | V13: =IF(AND(20>=9, 20<9+UsefulLife), K2/UsefulLife, 0) -> 0 | W13: =IF(AND(21>=9, 21<9+UsefulLife), K2/UsefulLife, 0) -> 0 | X13: =IF(AND(22>=9, 22<9+UsefulLife), K2/UsefulLife, 0) -> 0 | Y13: =IF(AND(23>=9, 23<9+UsefulLife), K2/UsefulLife, 0) -> 0 | Z13: =IF(AND(24>=9, 24<9+UsefulLife), K2/UsefulLife, 0) -> 0 | AA13: =IF(AND(25>=9, 25<9+UsefulLife), K2/UsefulLife, 0) -> 0 | AB13: =IF(AND(26>=9, 26<9+UsefulLife), K2/UsefulLife, 0) -> 0 | AC13: =IF(AND(27>=9, 27<9+UsefulLife), K2/UsefulLife, 0) -> 0 | AD13: =IF(AND(28>=9, 28<9+UsefulLife), K2/UsefulLife, 0) -> 0 | AE13: =IF(AND(29>=9, 29<9+UsefulLife), K2/UsefulLife, 0) -> 0 | AF13: =IF(AND(30>=9, 30<9+UsefulLife), K2/UsefulLife, 0) -> 0 | AG13: =IF(AND(31>=9, 31<9+UsefulLife), K2/UsefulLife, 0) -> 0 | AH13: =IF(AND(32>=9, 32<9+UsefulLife), K2/UsefulLife, 0) -> 0 | AI13: =IF(AND(33>=9, 33<9+UsefulLife), K2/UsefulLife, 0) -> 0 | AJ13: =IF(AND(34>=9, 34<9+UsefulLife), K2/UsefulLife, 0) -> 0 | AK13: =IF(AND(35>=9, 35<9+UsefulLife), K2/UsefulLife, 0) -> 0
A14: Batch Nov-25 | B14: =IF(AND(0>=10, 0<10+UsefulLife), L2/UsefulLife, 0) -> 0 | C14: =IF(AND(1>=10, 1<10+UsefulLife), L2/UsefulLife, 0) -> 0 | D14: =IF(AND(2>=10, 2<10+UsefulLife), L2/UsefulLife, 0) -> 0 | E14: =IF(AND(3>=10, 3<10+UsefulLife), L2/UsefulLife, 0) -> 0 | F14: =IF(AND(4>=10, 4<10+UsefulLife), L2/UsefulLife, 0) -> 0 | G14: =IF(AND(5>=10, 5<10+UsefulLife), L2/UsefulLife, 0) -> 0 | H14: =IF(AND(6>=10, 6<10+UsefulLife), L2/UsefulLife, 0) -> 0 | I14: =IF(AND(7>=10, 7<10+UsefulLife), L2/UsefulLife, 0) -> 0 | J14: =IF(AND(8>=10, 8<10+UsefulLife), L2/UsefulLife, 0) -> 0 | K14: =IF(AND(9>=10, 9<10+UsefulLife), L2/UsefulLife, 0) -> 0 | L14: =IF(AND(10>=10, 10<10+UsefulLife), L2/UsefulLife, 0) -> 0 | M14: =IF(AND(11>=10, 11<10+UsefulLife), L2/UsefulLife, 0) -> 0 | N14: =IF(AND(12>=10, 12<10+UsefulLife), L2/UsefulLife, 0) -> 0 | O14: =IF(AND(13>=10, 13<10+UsefulLife), L2/UsefulLife, 0) -> 0 | P14: =IF(AND(14>=10, 14<10+UsefulLife), L2/UsefulLife, 0) -> 0 | Q14: =IF(AND(15>=10, 15<10+UsefulLife), L2/UsefulLife, 0) -> 0 | R14: =IF(AND(16>=10, 16<10+UsefulLife), L2/UsefulLife, 0) -> 0 | S14: =IF(AND(17>=10, 17<10+UsefulLife), L2/UsefulLife, 0) -> 0 | T14: =IF(AND(18>=10, 18<10+UsefulLife), L2/UsefulLife, 0) -> 0 | U14: =IF(AND(19>=10, 19<10+UsefulLife), L2/UsefulLife, 0) -> 0 | V14: =IF(AND(20>=10, 20<10+UsefulLife), L2/UsefulLife, 0) -> 0 | W14: =IF(AND(21>=10, 21<10+UsefulLife), L2/UsefulLife, 0) -> 0 | X14: =IF(AND(22>=10, 22<10+UsefulLife), L2/UsefulLife, 0) -> 0 | Y14: =IF(AND(23>=10, 23<10+UsefulLife), L2/UsefulLife, 0) -> 0 | Z14: =IF(AND(24>=10, 24<10+UsefulLife), L2/UsefulLife, 0) -> 0 | AA14: =IF(AND(25>=10, 25<10+UsefulLife), L2/UsefulLife, 0) -> 0 | AB14: =IF(AND(26>=10, 26<10+UsefulLife), L2/UsefulLife, 0) -> 0 | AC14: =IF(AND(27>=10, 27<10+UsefulLife), L2/UsefulLife, 0) -> 0 | AD14: =IF(AND(28>=10, 28<10+UsefulLife), L2/UsefulLife, 0) -> 0 | AE14: =IF(AND(29>=10, 29<10+UsefulLife), L2/UsefulLife, 0) -> 0 | AF14: =IF(AND(30>=10, 30<10+UsefulLife), L2/UsefulLife, 0) -> 0 | AG14: =IF(AND(31>=10, 31<10+UsefulLife), L2/UsefulLife, 0) -> 0 | AH14: =IF(AND(32>=10, 32<10+UsefulLife), L2/UsefulLife, 0) -> 0 | AI14: =IF(AND(33>=10, 33<10+UsefulLife), L2/UsefulLife, 0) -> 0 | AJ14: =IF(AND(34>=10, 34<10+UsefulLife), L2/UsefulLife, 0) -> 0 | AK14: =IF(AND(35>=10, 35<10+UsefulLife), L2/UsefulLife, 0) -> 0
A15: Batch Dec-25 | B15: =IF(AND(0>=11, 0<11+UsefulLife), M2/UsefulLife, 0) -> 0 | C15: =IF(AND(1>=11, 1<11+UsefulLife), M2/UsefulLife, 0) -> 0 | D15: =IF(AND(2>=11, 2<11+UsefulLife), M2/UsefulLife, 0) -> 0 | E15: =IF(AND(3>=11, 3<11+UsefulLife), M2/UsefulLife, 0) -> 0 | F15: =IF(AND(4>=11, 4<11+UsefulLife), M2/UsefulLife, 0) -> 0 | G15: =IF(AND(5>=11, 5<11+UsefulLife), M2/UsefulLife, 0) -> 0 | H15: =IF(AND(6>=11, 6<11+UsefulLife), M2/UsefulLife, 0) -> 0 | I15: =IF(AND(7>=11, 7<11+UsefulLife), M2/UsefulLife, 0) -> 0 | J15: =IF(AND(8>=11, 8<11+UsefulLife), M2/UsefulLife, 0) -> 0 | K15: =IF(AND(9>=11, 9<11+UsefulLife), M2/UsefulLife, 0) -> 0 | L15: =IF(AND(10>=11, 10<11+UsefulLife), M2/UsefulLife, 0) -> 0 | M15: =IF(AND(11>=11, 11<11+UsefulLife), M2/UsefulLife, 0) -> 0 | N15: =IF(AND(12>=11, 12<11+UsefulLife), M2/UsefulLife, 0) -> 0 | O15: =IF(AND(13>=11, 13<11+UsefulLife), M2/UsefulLife, 0) -> 0 | P15: =IF(AND(14>=11, 14<11+UsefulLife), M2/UsefulLife, 0) -> 0 | Q15: =IF(AND(15>=11, 15<11+UsefulLife), M2/UsefulLife, 0) -> 0 | R15: =IF(AND(16>=11, 16<11+UsefulLife), M2/UsefulLife, 0) -> 0 | S15: =IF(AND(17>=11, 17<11+UsefulLife), M2/UsefulLife, 0) -> 0 | T15: =IF(AND(18>=11, 18<11+UsefulLife), M2/UsefulLife, 0) -> 0 | U15: =IF(AND(19>=11, 19<11+UsefulLife), M2/UsefulLife, 0) -> 0 | V15: =IF(AND(20>=11, 20<11+UsefulLife), M2/UsefulLife, 0) -> 0 | W15: =IF(AND(21>=11, 21<11+UsefulLife), M2/UsefulLife, 0) -> 0 | X15: =IF(AND(22>=11, 22<11+UsefulLife), M2/UsefulLife, 0) -> 0 | Y15: =IF(AND(23>=11, 23<11+UsefulLife), M2/UsefulLife, 0) -> 0 | Z15: =IF(AND(24>=11, 24<11+UsefulLife), M2/UsefulLife, 0) -> 0 | AA15: =IF(AND(25>=11, 25<11+UsefulLife), M2/UsefulLife, 0) -> 0 | AB15: =IF(AND(26>=11, 26<11+UsefulLife), M2/UsefulLife, 0) -> 0 | AC15: =IF(AND(27>=11, 27<11+UsefulLife), M2/UsefulLife, 0) -> 0 | AD15: =IF(AND(28>=11, 28<11+UsefulLife), M2/UsefulLife, 0) -> 0 | AE15: =IF(AND(29>=11, 29<11+UsefulLife), M2/UsefulLife, 0) -> 0 | AF15: =IF(AND(30>=11, 30<11+UsefulLife), M2/UsefulLife, 0) -> 0 | AG15: =IF(AND(31>=11, 31<11+UsefulLife), M2/UsefulLife, 0) -> 0 | AH15: =IF(AND(32>=11, 32<11+UsefulLife), M2/UsefulLife, 0) -> 0 | AI15: =IF(AND(33>=11, 33<11+UsefulLife), M2/UsefulLife, 0) -> 0 | AJ15: =IF(AND(34>=11, 34<11+UsefulLife), M2/UsefulLife, 0) -> 0 | AK15: =IF(AND(35>=11, 35<11+UsefulLife), M2/UsefulLife, 0) -> 0
A16: Batch Jan-26 | B16: =IF(AND(0>=12, 0<12+UsefulLife), N2/UsefulLife, 0) -> 0 | C16: =IF(AND(1>=12, 1<12+UsefulLife), N2/UsefulLife, 0) -> 0 | D16: =IF(AND(2>=12, 2<12+UsefulLife), N2/UsefulLife, 0) -> 0 | E16: =IF(AND(3>=12, 3<12+UsefulLife), N2/UsefulLife, 0) -> 0 | F16: =IF(AND(4>=12, 4<12+UsefulLife), N2/UsefulLife, 0) -> 0 | G16: =IF(AND(5>=12, 5<12+UsefulLife), N2/UsefulLife, 0) -> 0 | H16: =IF(AND(6>=12, 6<12+UsefulLife), N2/UsefulLife, 0) -> 0 | I16: =IF(AND(7>=12, 7<12+UsefulLife), N2/UsefulLife, 0) -> 0 | J16: =IF(AND(8>=12, 8<12+UsefulLife), N2/UsefulLife, 0) -> 0 | K16: =IF(AND(9>=12, 9<12+UsefulLife), N2/UsefulLife, 0) -> 0 | L16: =IF(AND(10>=12, 10<12+UsefulLife), N2/UsefulLife, 0) -> 0 | M16: =IF(AND(11>=12, 11<12+UsefulLife), N2/UsefulLife, 0) -> 0 | N16: =IF(AND(12>=12, 12<12+UsefulLife), N2/UsefulLife, 0) -> 0 | O16: =IF(AND(13>=12, 13<12+UsefulLife), N2/UsefulLife, 0) -> 0 | P16: =IF(AND(14>=12, 14<12+UsefulLife), N2/UsefulLife, 0) -> 0 | Q16: =IF(AND(15>=12, 15<12+UsefulLife), N2/UsefulLife, 0) -> 0 | R16: =IF(AND(16>=12, 16<12+UsefulLife), N2/UsefulLife, 0) -> 0 | S16: =IF(AND(17>=12, 17<12+UsefulLife), N2/UsefulLife, 0) -> 0 | T16: =IF(AND(18>=12, 18<12+UsefulLife), N2/UsefulLife, 0) -> 0 | U16: =IF(AND(19>=12, 19<12+UsefulLife), N2/UsefulLife, 0) -> 0 | V16: =IF(AND(20>=12, 20<12+UsefulLife), N2/UsefulLife, 0) -> 0 | W16: =IF(AND(21>=12, 21<12+UsefulLife), N2/UsefulLife, 0) -> 0 | X16: =IF(AND(22>=12, 22<12+UsefulLife), N2/UsefulLife, 0) -> 0 | Y16: =IF(AND(23>=12, 23<12+UsefulLife), N2/UsefulLife, 0) -> 0 | Z16: =IF(AND(24>=12, 24<12+UsefulLife), N2/UsefulLife, 0) -> 0 | AA16: =IF(AND(25>=12, 25<12+UsefulLife), N2/UsefulLife, 0) -> 0 | AB16: =IF(AND(26>=12, 26<12+UsefulLife), N2/UsefulLife, 0) -> 0 | AC16: =IF(AND(27>=12, 27<12+UsefulLife), N2/UsefulLife, 0) -> 0 | AD16: =IF(AND(28>=12, 28<12+UsefulLife), N2/UsefulLife, 0) -> 0 | AE16: =IF(AND(29>=12, 29<12+UsefulLife), N2/UsefulLife, 0) -> 0 | AF16: =IF(AND(30>=12, 30<12+UsefulLife), N2/UsefulLife, 0) -> 0 | AG16: =IF(AND(31>=12, 31<12+UsefulLife), N2/UsefulLife, 0) -> 0 | AH16: =IF(AND(32>=12, 32<12+UsefulLife), N2/UsefulLife, 0) -> 0 | AI16: =IF(AND(33>=12, 33<12+UsefulLife), N2/UsefulLife, 0) -> 0 | AJ16: =IF(AND(34>=12, 34<12+UsefulLife), N2/UsefulLife, 0) -> 0 | AK16: =IF(AND(35>=12, 35<12+UsefulLife), N2/UsefulLife, 0) -> 0
A17: Batch Feb-26 | B17: =IF(AND(0>=13, 0<13+UsefulLife), O2/UsefulLife, 0) -> 0 | C17: =IF(AND(1>=13, 1<13+UsefulLife), O2/UsefulLife, 0) -> 0 | D17: =IF(AND(2>=13, 2<13+UsefulLife), O2/UsefulLife, 0) -> 0 | E17: =IF(AND(3>=13, 3<13+UsefulLife), O2/UsefulLife, 0) -> 0 | F17: =IF(AND(4>=13, 4<13+UsefulLife), O2/UsefulLife, 0) -> 0 | G17: =IF(AND(5>=13, 5<13+UsefulLife), O2/UsefulLife, 0) -> 0 | H17: =IF(AND(6>=13, 6<13+UsefulLife), O2/UsefulLife, 0) -> 0 | I17: =IF(AND(7>=13, 7<13+UsefulLife), O2/UsefulLife, 0) -> 0 | J17: =IF(AND(8>=13, 8<13+UsefulLife), O2/UsefulLife, 0) -> 0 | K17: =IF(AND(9>=13, 9<13+UsefulLife), O2/UsefulLife, 0) -> 0 | L17: =IF(AND(10>=13, 10<13+UsefulLife), O2/UsefulLife, 0) -> 0 | M17: =IF(AND(11>=13, 11<13+UsefulLife), O2/UsefulLife, 0) -> 0 | N17: =IF(AND(12>=13, 12<13+UsefulLife), O2/UsefulLife, 0) -> 0 | O17: =IF(AND(13>=13, 13<13+UsefulLife), O2/UsefulLife, 0) -> 0 | P17: =IF(AND(14>=13, 14<13+UsefulLife), O2/UsefulLife, 0) -> 0 | Q17: =IF(AND(15>=13, 15<13+UsefulLife), O2/UsefulLife, 0) -> 0 | R17: =IF(AND(16>=13, 16<13+UsefulLife), O2/UsefulLife, 0) -> 0 | S17: =IF(AND(17>=13, 17<13+UsefulLife), O2/UsefulLife, 0) -> 0 | T17: =IF(AND(18>=13, 18<13+UsefulLife), O2/UsefulLife, 0) -> 0 | U17: =IF(AND(19>=13, 19<13+UsefulLife), O2/UsefulLife, 0) -> 0 | V17: =IF(AND(20>=13, 20<13+UsefulLife), O2/UsefulLife, 0) -> 0 | W17: =IF(AND(21>=13, 21<13+UsefulLife), O2/UsefulLife, 0) -> 0 | X17: =IF(AND(22>=13, 22<13+UsefulLife), O2/UsefulLife, 0) -> 0 | Y17: =IF(AND(23>=13, 23<13+UsefulLife), O2/UsefulLife, 0) -> 0 | Z17: =IF(AND(24>=13, 24<13+UsefulLife), O2/UsefulLife, 0) -> 0 | AA17: =IF(AND(25>=13, 25<13+UsefulLife), O2/UsefulLife, 0) -> 0 | AB17: =IF(AND(26>=13, 26<13+UsefulLife), O2/UsefulLife, 0) -> 0 | AC17: =IF(AND(27>=13, 27<13+UsefulLife), O2/UsefulLife, 0) -> 0 | AD17: =IF(AND(28>=13, 28<13+UsefulLife), O2/UsefulLife, 0) -> 0 | AE17: =IF(AND(29>=13, 29<13+UsefulLife), O2/UsefulLife, 0) -> 0 | AF17: =IF(AND(30>=13, 30<13+UsefulLife), O2/UsefulLife, 0) -> 0 | AG17: =IF(AND(31>=13, 31<13+UsefulLife), O2/UsefulLife, 0) -> 0 | AH17: =IF(AND(32>=13, 32<13+UsefulLife), O2/UsefulLife, 0) -> 0 | AI17: =IF(AND(33>=13, 33<13+UsefulLife), O2/UsefulLife, 0) -> 0 | AJ17: =IF(AND(34>=13, 34<13+UsefulLife), O2/UsefulLife, 0) -> 0 | AK17: =IF(AND(35>=13, 35<13+UsefulLife), O2/UsefulLife, 0) -> 0
A18: Batch Mar-26 | B18: =IF(AND(0>=14, 0<14+UsefulLife), P2/UsefulLife, 0) -> 0 | C18: =IF(AND(1>=14, 1<14+UsefulLife), P2/UsefulLife, 0) -> 0 | D18: =IF(AND(2>=14, 2<14+UsefulLife), P2/UsefulLife, 0) -> 0 | E18: =IF(AND(3>=14, 3<14+UsefulLife), P2/UsefulLife, 0) -> 0 | F18: =IF(AND(4>=14, 4<14+UsefulLife), P2/UsefulLife, 0) -> 0 | G18: =IF(AND(5>=14, 5<14+UsefulLife), P2/UsefulLife, 0) -> 0 | H18: =IF(AND(6>=14, 6<14+UsefulLife), P2/UsefulLife, 0) -> 0 | I18: =IF(AND(7>=14, 7<14+UsefulLife), P2/UsefulLife, 0) -> 0 | J18: =IF(AND(8>=14, 8<14+UsefulLife), P2/UsefulLife, 0) -> 0 | K18: =IF(AND(9>=14, 9<14+UsefulLife), P2/UsefulLife, 0) -> 0 | L18: =IF(AND(10>=14, 10<14+UsefulLife), P2/UsefulLife, 0) -> 0 | M18: =IF(AND(11>=14, 11<14+UsefulLife), P2/UsefulLife, 0) -> 0 | N18: =IF(AND(12>=14, 12<14+UsefulLife), P2/UsefulLife, 0) -> 0 | O18: =IF(AND(13>=14, 13<14+UsefulLife), P2/UsefulLife, 0) -> 0 | P18: =IF(AND(14>=14, 14<14+UsefulLife), P2/UsefulLife, 0) -> 0 | Q18: =IF(AND(15>=14, 15<14+UsefulLife), P2/UsefulLife, 0) -> 0 | R18: =IF(AND(16>=14, 16<14+UsefulLife), P2/UsefulLife, 0) -> 0 | S18: =IF(AND(17>=14, 17<14+UsefulLife), P2/UsefulLife, 0) -> 0 | T18: =IF(AND(18>=14, 18<14+UsefulLife), P2/UsefulLife, 0) -> 0 | U18: =IF(AND(19>=14, 19<14+UsefulLife), P2/UsefulLife, 0) -> 0 | V18: =IF(AND(20>=14, 20<14+UsefulLife), P2/UsefulLife, 0) -> 0 | W18: =IF(AND(21>=14, 21<14+UsefulLife), P2/UsefulLife, 0) -> 0 | X18: =IF(AND(22>=14, 22<14+UsefulLife), P2/UsefulLife, 0) -> 0 | Y18: =IF(AND(23>=14, 23<14+UsefulLife), P2/UsefulLife, 0) -> 0 | Z18: =IF(AND(24>=14, 24<14+UsefulLife), P2/UsefulLife, 0) -> 0 | AA18: =IF(AND(25>=14, 25<14+UsefulLife), P2/UsefulLife, 0) -> 0 | AB18: =IF(AND(26>=14, 26<14+UsefulLife), P2/UsefulLife, 0) -> 0 | AC18: =IF(AND(27>=14, 27<14+UsefulLife), P2/UsefulLife, 0) -> 0 | AD18: =IF(AND(28>=14, 28<14+UsefulLife), P2/UsefulLife, 0) -> 0 | AE18: =IF(AND(29>=14, 29<14+UsefulLife), P2/UsefulLife, 0) -> 0 | AF18: =IF(AND(30>=14, 30<14+UsefulLife), P2/UsefulLife, 0) -> 0 | AG18: =IF(AND(31>=14, 31<14+UsefulLife), P2/UsefulLife, 0) -> 0 | AH18: =IF(AND(32>=14, 32<14+UsefulLife), P2/UsefulLife, 0) -> 0 | AI18: =IF(AND(33>=14, 33<14+UsefulLife), P2/UsefulLife, 0) -> 0 | AJ18: =IF(AND(34>=14, 34<14+UsefulLife), P2/UsefulLife, 0) -> 0 | AK18: =IF(AND(35>=14, 35<14+UsefulLife), P2/UsefulLife, 0) -> 0
A19: Batch Apr-26 | B19: =IF(AND(0>=15, 0<15+UsefulLife), Q2/UsefulLife, 0) -> 0 | C19: =IF(AND(1>=15, 1<15+UsefulLife), Q2/UsefulLife, 0) -> 0 | D19: =IF(AND(2>=15, 2<15+UsefulLife), Q2/UsefulLife, 0) -> 0 | E19: =IF(AND(3>=15, 3<15+UsefulLife), Q2/UsefulLife, 0) -> 0 | F19: =IF(AND(4>=15, 4<15+UsefulLife), Q2/UsefulLife, 0) -> 0 | G19: =IF(AND(5>=15, 5<15+UsefulLife), Q2/UsefulLife, 0) -> 0 | H19: =IF(AND(6>=15, 6<15+UsefulLife), Q2/UsefulLife, 0) -> 0 | I19: =IF(AND(7>=15, 7<15+UsefulLife), Q2/UsefulLife, 0) -> 0 | J19: =IF(AND(8>=15, 8<15+UsefulLife), Q2/UsefulLife, 0) -> 0 | K19: =IF(AND(9>=15, 9<15+UsefulLife), Q2/UsefulLife, 0) -> 0 | L19: =IF(AND(10>=15, 10<15+UsefulLife), Q2/UsefulLife, 0) -> 0 | M19: =IF(AND(11>=15, 11<15+UsefulLife), Q2/UsefulLife, 0) -> 0 | N19: =IF(AND(12>=15, 12<15+UsefulLife), Q2/UsefulLife, 0) -> 0 | O19: =IF(AND(13>=15, 13<15+UsefulLife), Q2/UsefulLife, 0) -> 0 | P19: =IF(AND(14>=15, 14<15+UsefulLife), Q2/UsefulLife, 0) -> 0 | Q19: =IF(AND(15>=15, 15<15+UsefulLife), Q2/UsefulLife, 0) -> 0 | R19: =IF(AND(16>=15, 16<15+UsefulLife), Q2/UsefulLife, 0) -> 0 | S19: =IF(AND(17>=15, 17<15+UsefulLife), Q2/UsefulLife, 0) -> 0 | T19: =IF(AND(18>=15, 18<15+UsefulLife), Q2/UsefulLife, 0) -> 0 | U19: =IF(AND(19>=15, 19<15+UsefulLife), Q2/UsefulLife, 0) -> 0 | V19: =IF(AND(20>=15, 20<15+UsefulLife), Q2/UsefulLife, 0) -> 0 | W19: =IF(AND(21>=15, 21<15+UsefulLife), Q2/UsefulLife, 0) -> 0 | X19: =IF(AND(22>=15, 22<15+UsefulLife), Q2/UsefulLife, 0) -> 0 | Y19: =IF(AND(23>=15, 23<15+UsefulLife), Q2/UsefulLife, 0) -> 0 | Z19: =IF(AND(24>=15, 24<15+UsefulLife), Q2/UsefulLife, 0) -> 0 | AA19: =IF(AND(25>=15, 25<15+UsefulLife), Q2/UsefulLife, 0) -> 0 | AB19: =IF(AND(26>=15, 26<15+UsefulLife), Q2/UsefulLife, 0) -> 0 | AC19: =IF(AND(27>=15, 27<15+UsefulLife), Q2/UsefulLife, 0) -> 0 | AD19: =IF(AND(28>=15, 28<15+UsefulLife), Q2/UsefulLife, 0) -> 0 | AE19: =IF(AND(29>=15, 29<15+UsefulLife), Q2/UsefulLife, 0) -> 0 | AF19: =IF(AND(30>=15, 30<15+UsefulLife), Q2/UsefulLife, 0) -> 0 | AG19: =IF(AND(31>=15, 31<15+UsefulLife), Q2/UsefulLife, 0) -> 0 | AH19: =IF(AND(32>=15, 32<15+UsefulLife), Q2/UsefulLife, 0) -> 0 | AI19: =IF(AND(33>=15, 33<15+UsefulLife), Q2/UsefulLife, 0) -> 0 | AJ19: =IF(AND(34>=15, 34<15+UsefulLife), Q2/UsefulLife, 0) -> 0 | AK19: =IF(AND(35>=15, 35<15+UsefulLife), Q2/UsefulLife, 0) -> 0
A20: Batch May-26 | B20: =IF(AND(0>=16, 0<16+UsefulLife), R2/UsefulLife, 0) -> 0 | C20: =IF(AND(1>=16, 1<16+UsefulLife), R2/UsefulLife, 0) -> 0 | D20: =IF(AND(2>=16, 2<16+UsefulLife), R2/UsefulLife, 0) -> 0 | E20: =IF(AND(3>=16, 3<16+UsefulLife), R2/UsefulLife, 0) -> 0 | F20: =IF(AND(4>=16, 4<16+UsefulLife), R2/UsefulLife, 0) -> 0 | G20: =IF(AND(5>=16, 5<16+UsefulLife), R2/UsefulLife, 0) -> 0 | H20: =IF(AND(6>=16, 6<16+UsefulLife), R2/UsefulLife, 0) -> 0 | I20: =IF(AND(7>=16, 7<16+UsefulLife), R2/UsefulLife, 0) -> 0 | J20: =IF(AND(8>=16, 8<16+UsefulLife), R2/UsefulLife, 0) -> 0 | K20: =IF(AND(9>=16, 9<16+UsefulLife), R2/UsefulLife, 0) -> 0 | L20: =IF(AND(10>=16, 10<16+UsefulLife), R2/UsefulLife, 0) -> 0 | M20: =IF(AND(11>=16, 11<16+UsefulLife), R2/UsefulLife, 0) -> 0 | N20: =IF(AND(12>=16, 12<16+UsefulLife), R2/UsefulLife, 0) -> 0 | O20: =IF(AND(13>=16, 13<16+UsefulLife), R2/UsefulLife, 0) -> 0 | P20: =IF(AND(14>=16, 14<16+UsefulLife), R2/UsefulLife, 0) -> 0 | Q20: =IF(AND(15>=16, 15<16+UsefulLife), R2/UsefulLife, 0) -> 0 | R20: =IF(AND(16>=16, 16<16+UsefulLife), R2/UsefulLife, 0) -> 0 | S20: =IF(AND(17>=16, 17<16+UsefulLife), R2/UsefulLife, 0) -> 0 | T20: =IF(AND(18>=16, 18<16+UsefulLife), R2/UsefulLife, 0) -> 0 | U20: =IF(AND(19>=16, 19<16+UsefulLife), R2/UsefulLife, 0) -> 0 | V20: =IF(AND(20>=16, 20<16+UsefulLife), R2/UsefulLife, 0) -> 0 | W20: =IF(AND(21>=16, 21<16+UsefulLife), R2/UsefulLife, 0) -> 0 | X20: =IF(AND(22>=16, 22<16+UsefulLife), R2/UsefulLife, 0) -> 0 | Y20: =IF(AND(23>=16, 23<16+UsefulLife), R2/UsefulLife, 0) -> 0 | Z20: =IF(AND(24>=16, 24<16+UsefulLife), R2/UsefulLife, 0) -> 0 | AA20: =IF(AND(25>=16, 25<16+UsefulLife), R2/UsefulLife, 0) -> 0 | AB20: =IF(AND(26>=16, 26<16+UsefulLife), R2/UsefulLife, 0) -> 0 | AC20: =IF(AND(27>=16, 27<16+UsefulLife), R2/UsefulLife, 0) -> 0 | AD20: =IF(AND(28>=16, 28<16+UsefulLife), R2/UsefulLife, 0) -> 0 | AE20: =IF(AND(29>=16, 29<16+UsefulLife), R2/UsefulLife, 0) -> 0 | AF20: =IF(AND(30>=16, 30<16+UsefulLife), R2/UsefulLife, 0) -> 0 | AG20: =IF(AND(31>=16, 31<16+UsefulLife), R2/UsefulLife, 0) -> 0 | AH20: =IF(AND(32>=16, 32<16+UsefulLife), R2/UsefulLife, 0) -> 0 | AI20: =IF(AND(33>=16, 33<16+UsefulLife), R2/UsefulLife, 0) -> 0 | AJ20: =IF(AND(34>=16, 34<16+UsefulLife), R2/UsefulLife, 0) -> 0 | AK20: =IF(AND(35>=16, 35<16+UsefulLife), R2/UsefulLife, 0) -> 0
A21: Batch Jun-26 | B21: =IF(AND(0>=17, 0<17+UsefulLife), S2/UsefulLife, 0) -> 0 | C21: =IF(AND(1>=17, 1<17+UsefulLife), S2/UsefulLife, 0) -> 0 | D21: =IF(AND(2>=17, 2<17+UsefulLife), S2/UsefulLife, 0) -> 0 | E21: =IF(AND(3>=17, 3<17+UsefulLife), S2/UsefulLife, 0) -> 0 | F21: =IF(AND(4>=17, 4<17+UsefulLife), S2/UsefulLife, 0) -> 0 | G21: =IF(AND(5>=17, 5<17+UsefulLife), S2/UsefulLife, 0) -> 0 | H21: =IF(AND(6>=17, 6<17+UsefulLife), S2/UsefulLife, 0) -> 0 | I21: =IF(AND(7>=17, 7<17+UsefulLife), S2/UsefulLife, 0) -> 0 | J21: =IF(AND(8>=17, 8<17+UsefulLife), S2/UsefulLife, 0) -> 0 | K21: =IF(AND(9>=17, 9<17+UsefulLife), S2/UsefulLife, 0) -> 0 | L21: =IF(AND(10>=17, 10<17+UsefulLife), S2/UsefulLife, 0) -> 0 | M21: =IF(AND(11>=17, 11<17+UsefulLife), S2/UsefulLife, 0) -> 0 | N21: =IF(AND(12>=17, 12<17+UsefulLife), S2/UsefulLife, 0) -> 0 | O21: =IF(AND(13>=17, 13<17+UsefulLife), S2/UsefulLife, 0) -> 0 | P21: =IF(AND(14>=17, 14<17+UsefulLife), S2/UsefulLife, 0) -> 0 | Q21: =IF(AND(15>=17, 15<17+UsefulLife), S2/UsefulLife, 0) -> 0 | R21: =IF(AND(16>=17, 16<17+UsefulLife), S2/UsefulLife, 0) -> 0 | S21: =IF(AND(17>=17, 17<17+UsefulLife), S2/UsefulLife, 0) -> 0 | T21: =IF(AND(18>=17, 18<17+UsefulLife), S2/UsefulLife, 0) -> 0 | U21: =IF(AND(19>=17, 19<17+UsefulLife), S2/UsefulLife, 0) -> 0 | V21: =IF(AND(20>=17, 20<17+UsefulLife), S2/UsefulLife, 0) -> 0 | W21: =IF(AND(21>=17, 21<17+UsefulLife), S2/UsefulLife, 0) -> 0 | X21: =IF(AND(22>=17, 22<17+UsefulLife), S2/UsefulLife, 0) -> 0 | Y21: =IF(AND(23>=17, 23<17+UsefulLife), S2/UsefulLife, 0) -> 0 | Z21: =IF(AND(24>=17, 24<17+UsefulLife), S2/UsefulLife, 0) -> 0 | AA21: =IF(AND(25>=17, 25<17+UsefulLife), S2/UsefulLife, 0) -> 0 | AB21: =IF(AND(26>=17, 26<17+UsefulLife), S2/UsefulLife, 0) -> 0 | AC21: =IF(AND(27>=17, 27<17+UsefulLife), S2/UsefulLife, 0) -> 0 | AD21: =IF(AND(28>=17, 28<17+UsefulLife), S2/UsefulLife, 0) -> 0 | AE21: =IF(AND(29>=17, 29<17+UsefulLife), S2/UsefulLife, 0) -> 0 | AF21: =IF(AND(30>=17, 30<17+UsefulLife), S2/UsefulLife, 0) -> 0 | AG21: =IF(AND(31>=17, 31<17+UsefulLife), S2/UsefulLife, 0) -> 0 | AH21: =IF(AND(32>=17, 32<17+UsefulLife), S2/UsefulLife, 0) -> 0 | AI21: =IF(AND(33>=17, 33<17+UsefulLife), S2/UsefulLife, 0) -> 0 | AJ21: =IF(AND(34>=17, 34<17+UsefulLife), S2/UsefulLife, 0) -> 0 | AK21: =IF(AND(35>=17, 35<17+UsefulLife), S2/UsefulLife, 0) -> 0
A22: Batch Jul-26 | B22: =IF(AND(0>=18, 0<18+UsefulLife), T2/UsefulLife, 0) -> 0 | C22: =IF(AND(1>=18, 1<18+UsefulLife), T2/UsefulLife, 0) -> 0 | D22: =IF(AND(2>=18, 2<18+UsefulLife), T2/UsefulLife, 0) -> 0 | E22: =IF(AND(3>=18, 3<18+UsefulLife), T2/UsefulLife, 0) -> 0 | F22: =IF(AND(4>=18, 4<18+UsefulLife), T2/UsefulLife, 0) -> 0 | G22: =IF(AND(5>=18, 5<18+UsefulLife), T2/UsefulLife, 0) -> 0 | H22: =IF(AND(6>=18, 6<18+UsefulLife), T2/UsefulLife, 0) -> 0 | I22: =IF(AND(7>=18, 7<18+UsefulLife), T2/UsefulLife, 0) -> 0 | J22: =IF(AND(8>=18, 8<18+UsefulLife), T2/UsefulLife, 0) -> 0 | K22: =IF(AND(9>=18, 9<18+UsefulLife), T2/UsefulLife, 0) -> 0 | L22: =IF(AND(10>=18, 10<18+UsefulLife), T2/UsefulLife, 0) -> 0 | M22: =IF(AND(11>=18, 11<18+UsefulLife), T2/UsefulLife, 0) -> 0 | N22: =IF(AND(12>=18, 12<18+UsefulLife), T2/UsefulLife, 0) -> 0 | O22: =IF(AND(13>=18, 13<18+UsefulLife), T2/UsefulLife, 0) -> 0 | P22: =IF(AND(14>=18, 14<18+UsefulLife), T2/UsefulLife, 0) -> 0 | Q22: =IF(AND(15>=18, 15<18+UsefulLife), T2/UsefulLife, 0) -> 0 | R22: =IF(AND(16>=18, 16<18+UsefulLife), T2/UsefulLife, 0) -> 0 | S22: =IF(AND(17>=18, 17<18+UsefulLife), T2/UsefulLife, 0) -> 0 | T22: =IF(AND(18>=18, 18<18+UsefulLife), T2/UsefulLife, 0) -> 0 | U22: =IF(AND(19>=18, 19<18+UsefulLife), T2/UsefulLife, 0) -> 0 | V22: =IF(AND(20>=18, 20<18+UsefulLife), T2/UsefulLife, 0) -> 0 | W22: =IF(AND(21>=18, 21<18+UsefulLife), T2/UsefulLife, 0) -> 0 | X22: =IF(AND(22>=18, 22<18+UsefulLife), T2/UsefulLife, 0) -> 0 | Y22: =IF(AND(23>=18, 23<18+UsefulLife), T2/UsefulLife, 0) -> 0 | Z22: =IF(AND(24>=18, 24<18+UsefulLife), T2/UsefulLife, 0) -> 0 | AA22: =IF(AND(25>=18, 25<18+UsefulLife), T2/UsefulLife, 0) -> 0 | AB22: =IF(AND(26>=18, 26<18+UsefulLife), T2/UsefulLife, 0) -> 0 | AC22: =IF(AND(27>=18, 27<18+UsefulLife), T2/UsefulLife, 0) -> 0 | AD22: =IF(AND(28>=18, 28<18+UsefulLife), T2/UsefulLife, 0) -> 0 | AE22: =IF(AND(29>=18, 29<18+UsefulLife), T2/UsefulLife, 0) -> 0 | AF22: =IF(AND(30>=18, 30<18+UsefulLife), T2/UsefulLife, 0) -> 0 | AG22: =IF(AND(31>=18, 31<18+UsefulLife), T2/UsefulLife, 0) -> 0 | AH22: =IF(AND(32>=18, 32<18+UsefulLife), T2/UsefulLife, 0) -> 0 | AI22: =IF(AND(33>=18, 33<18+UsefulLife), T2/UsefulLife, 0) -> 0 | AJ22: =IF(AND(34>=18, 34<18+UsefulLife), T2/UsefulLife, 0) -> 0 | AK22: =IF(AND(35>=18, 35<18+UsefulLife), T2/UsefulLife, 0) -> 0
A23: Batch Aug-26 | B23: =IF(AND(0>=19, 0<19+UsefulLife), U2/UsefulLife, 0) -> 0 | C23: =IF(AND(1>=19, 1<19+UsefulLife), U2/UsefulLife, 0) -> 0 | D23: =IF(AND(2>=19, 2<19+UsefulLife), U2/UsefulLife, 0) -> 0 | E23: =IF(AND(3>=19, 3<19+UsefulLife), U2/UsefulLife, 0) -> 0 | F23: =IF(AND(4>=19, 4<19+UsefulLife), U2/UsefulLife, 0) -> 0 | G23: =IF(AND(5>=19, 5<19+UsefulLife), U2/UsefulLife, 0) -> 0 | H23: =IF(AND(6>=19, 6<19+UsefulLife), U2/UsefulLife, 0) -> 0 | I23: =IF(AND(7>=19, 7<19+UsefulLife), U2/UsefulLife, 0) -> 0 | J23: =IF(AND(8>=19, 8<19+UsefulLife), U2/UsefulLife, 0) -> 0 | K23: =IF(AND(9>=19, 9<19+UsefulLife), U2/UsefulLife, 0) -> 0 | L23: =IF(AND(10>=19, 10<19+UsefulLife), U2/UsefulLife, 0) -> 0 | M23: =IF(AND(11>=19, 11<19+UsefulLife), U2/UsefulLife, 0) -> 0 | N23: =IF(AND(12>=19, 12<19+UsefulLife), U2/UsefulLife, 0) -> 0 | O23: =IF(AND(13>=19, 13<19+UsefulLife), U2/UsefulLife, 0) -> 0 | P23: =IF(AND(14>=19, 14<19+UsefulLife), U2/UsefulLife, 0) -> 0 | Q23: =IF(AND(15>=19, 15<19+UsefulLife), U2/UsefulLife, 0) -> 0 | R23: =IF(AND(16>=19, 16<19+UsefulLife), U2/UsefulLife, 0) -> 0 | S23: =IF(AND(17>=19, 17<19+UsefulLife), U2/UsefulLife, 0) -> 0 | T23: =IF(AND(18>=19, 18<19+UsefulLife), U2/UsefulLife, 0) -> 0 | U23: =IF(AND(19>=19, 19<19+UsefulLife), U2/UsefulLife, 0) -> 0 | V23: =IF(AND(20>=19, 20<19+UsefulLife), U2/UsefulLife, 0) -> 0 | W23: =IF(AND(21>=19, 21<19+UsefulLife), U2/UsefulLife, 0) -> 0 | X23: =IF(AND(22>=19, 22<19+UsefulLife), U2/UsefulLife, 0) -> 0 | Y23: =IF(AND(23>=19, 23<19+UsefulLife), U2/UsefulLife, 0) -> 0 | Z23: =IF(AND(24>=19, 24<19+UsefulLife), U2/UsefulLife, 0) -> 0 | AA23: =IF(AND(25>=19, 25<19+UsefulLife), U2/UsefulLife, 0) -> 0 | AB23: =IF(AND(26>=19, 26<19+UsefulLife), U2/UsefulLife, 0) -> 0 | AC23: =IF(AND(27>=19, 27<19+UsefulLife), U2/UsefulLife, 0) -> 0 | AD23: =IF(AND(28>=19, 28<19+UsefulLife), U2/UsefulLife, 0) -> 0 | AE23: =IF(AND(29>=19, 29<19+UsefulLife), U2/UsefulLife, 0) -> 0 | AF23: =IF(AND(30>=19, 30<19+UsefulLife), U2/UsefulLife, 0) -> 0 | AG23: =IF(AND(31>=19, 31<19+UsefulLife), U2/UsefulLife, 0) -> 0 | AH23: =IF(AND(32>=19, 32<19+UsefulLife), U2/UsefulLife, 0) -> 0 | AI23: =IF(AND(33>=19, 33<19+UsefulLife), U2/UsefulLife, 0) -> 0 | AJ23: =IF(AND(34>=19, 34<19+UsefulLife), U2/UsefulLife, 0) -> 0 | AK23: =IF(AND(35>=19, 35<19+UsefulLife), U2/UsefulLife, 0) -> 0
A24: Batch Sep-26 | B24: =IF(AND(0>=20, 0<20+UsefulLife), V2/UsefulLife, 0) -> 0 | C24: =IF(AND(1>=20, 1<20+UsefulLife), V2/UsefulLife, 0) -> 0 | D24: =IF(AND(2>=20, 2<20+UsefulLife), V2/UsefulLife, 0) -> 0 | E24: =IF(AND(3>=20, 3<20+UsefulLife), V2/UsefulLife, 0) -> 0 | F24: =IF(AND(4>=20, 4<20+UsefulLife), V2/UsefulLife, 0) -> 0 | G24: =IF(AND(5>=20, 5<20+UsefulLife), V2/UsefulLife, 0) -> 0 | H24: =IF(AND(6>=20, 6<20+UsefulLife), V2/UsefulLife, 0) -> 0 | I24: =IF(AND(7>=20, 7<20+UsefulLife), V2/UsefulLife, 0) -> 0 | J24: =IF(AND(8>=20, 8<20+UsefulLife), V2/UsefulLife, 0) -> 0 | K24: =IF(AND(9>=20, 9<20+UsefulLife), V2/UsefulLife, 0) -> 0 | L24: =IF(AND(10>=20, 10<20+UsefulLife), V2/UsefulLife, 0) -> 0 | M24: =IF(AND(11>=20, 11<20+UsefulLife), V2/UsefulLife, 0) -> 0 | N24: =IF(AND(12>=20, 12<20+UsefulLife), V2/UsefulLife, 0) -> 0 | O24: =IF(AND(13>=20, 13<20+UsefulLife), V2/UsefulLife, 0) -> 0 | P24: =IF(AND(14>=20, 14<20+UsefulLife), V2/UsefulLife, 0) -> 0 | Q24: =IF(AND(15>=20, 15<20+UsefulLife), V2/UsefulLife, 0) -> 0 | R24: =IF(AND(16>=20, 16<20+UsefulLife), V2/UsefulLife, 0) -> 0 | S24: =IF(AND(17>=20, 17<20+UsefulLife), V2/UsefulLife, 0) -> 0 | T24: =IF(AND(18>=20, 18<20+UsefulLife), V2/UsefulLife, 0) -> 0 | U24: =IF(AND(19>=20, 19<20+UsefulLife), V2/UsefulLife, 0) -> 0 | V24: =IF(AND(20>=20, 20<20+UsefulLife), V2/UsefulLife, 0) -> 0 | W24: =IF(AND(21>=20, 21<20+UsefulLife), V2/UsefulLife, 0) -> 0 | X24: =IF(AND(22>=20, 22<20+UsefulLife), V2/UsefulLife, 0) -> 0 | Y24: =IF(AND(23>=20, 23<20+UsefulLife), V2/UsefulLife, 0) -> 0 | Z24: =IF(AND(24>=20, 24<20+UsefulLife), V2/UsefulLife, 0) -> 0 | AA24: =IF(AND(25>=20, 25<20+UsefulLife), V2/UsefulLife, 0) -> 0 | AB24: =IF(AND(26>=20, 26<20+UsefulLife), V2/UsefulLife, 0) -> 0 | AC24: =IF(AND(27>=20, 27<20+UsefulLife), V2/UsefulLife, 0) -> 0 | AD24: =IF(AND(28>=20, 28<20+UsefulLife), V2/UsefulLife, 0) -> 0 | AE24: =IF(AND(29>=20, 29<20+UsefulLife), V2/UsefulLife, 0) -> 0 | AF24: =IF(AND(30>=20, 30<20+UsefulLife), V2/UsefulLife, 0) -> 0 | AG24: =IF(AND(31>=20, 31<20+UsefulLife), V2/UsefulLife, 0) -> 0 | AH24: =IF(AND(32>=20, 32<20+UsefulLife), V2/UsefulLife, 0) -> 0 | AI24: =IF(AND(33>=20, 33<20+UsefulLife), V2/UsefulLife, 0) -> 0 | AJ24: =IF(AND(34>=20, 34<20+UsefulLife), V2/UsefulLife, 0) -> 0 | AK24: =IF(AND(35>=20, 35<20+UsefulLife), V2/UsefulLife, 0) -> 0
A25: Batch Oct-26 | B25: =IF(AND(0>=21, 0<21+UsefulLife), W2/UsefulLife, 0) -> 0 | C25: =IF(AND(1>=21, 1<21+UsefulLife), W2/UsefulLife, 0) -> 0 | D25: =IF(AND(2>=21, 2<21+UsefulLife), W2/UsefulLife, 0) -> 0 | E25: =IF(AND(3>=21, 3<21+UsefulLife), W2/UsefulLife, 0) -> 0 | F25: =IF(AND(4>=21, 4<21+UsefulLife), W2/UsefulLife, 0) -> 0 | G25: =IF(AND(5>=21, 5<21+UsefulLife), W2/UsefulLife, 0) -> 0 | H25: =IF(AND(6>=21, 6<21+UsefulLife), W2/UsefulLife, 0) -> 0 | I25: =IF(AND(7>=21, 7<21+UsefulLife), W2/UsefulLife, 0) -> 0 | J25: =IF(AND(8>=21, 8<21+UsefulLife), W2/UsefulLife, 0) -> 0 | K25: =IF(AND(9>=21, 9<21+UsefulLife), W2/UsefulLife, 0) -> 0 | L25: =IF(AND(10>=21, 10<21+UsefulLife), W2/UsefulLife, 0) -> 0 | M25: =IF(AND(11>=21, 11<21+UsefulLife), W2/UsefulLife, 0) -> 0 | N25: =IF(AND(12>=21, 12<21+UsefulLife), W2/UsefulLife, 0) -> 0 | O25: =IF(AND(13>=21, 13<21+UsefulLife), W2/UsefulLife, 0) -> 0 | P25: =IF(AND(14>=21, 14<21+UsefulLife), W2/UsefulLife, 0) -> 0 | Q25: =IF(AND(15>=21, 15<21+UsefulLife), W2/UsefulLife, 0) -> 0 | R25: =IF(AND(16>=21, 16<21+UsefulLife), W2/UsefulLife, 0) -> 0 | S25: =IF(AND(17>=21, 17<21+UsefulLife), W2/UsefulLife, 0) -> 0 | T25: =IF(AND(18>=21, 18<21+UsefulLife), W2/UsefulLife, 0) -> 0 | U25: =IF(AND(19>=21, 19<21+UsefulLife), W2/UsefulLife, 0) -> 0 | V25: =IF(AND(20>=21, 20<21+UsefulLife), W2/UsefulLife, 0) -> 0 | W25: =IF(AND(21>=21, 21<21+UsefulLife), W2/UsefulLife, 0) -> 0 | X25: =IF(AND(22>=21, 22<21+UsefulLife), W2/UsefulLife, 0) -> 0 | Y25: =IF(AND(23>=21, 23<21+UsefulLife), W2/UsefulLife, 0) -> 0 | Z25: =IF(AND(24>=21, 24<21+UsefulLife), W2/UsefulLife, 0) -> 0 | AA25: =IF(AND(25>=21, 25<21+UsefulLife), W2/UsefulLife, 0) -> 0 | AB25: =IF(AND(26>=21, 26<21+UsefulLife), W2/UsefulLife, 0) -> 0 | AC25: =IF(AND(27>=21, 27<21+UsefulLife), W2/UsefulLife, 0) -> 0 | AD25: =IF(AND(28>=21, 28<21+UsefulLife), W2/UsefulLife, 0) -> 0 | AE25: =IF(AND(29>=21, 29<21+UsefulLife), W2/UsefulLife, 0) -> 0 | AF25: =IF(AND(30>=21, 30<21+UsefulLife), W2/UsefulLife, 0) -> 0 | AG25: =IF(AND(31>=21, 31<21+UsefulLife), W2/UsefulLife, 0) -> 0 | AH25: =IF(AND(32>=21, 32<21+UsefulLife), W2/UsefulLife, 0) -> 0 | AI25: =IF(AND(33>=21, 33<21+UsefulLife), W2/UsefulLife, 0) -> 0 | AJ25: =IF(AND(34>=21, 34<21+UsefulLife), W2/UsefulLife, 0) -> 0 | AK25: =IF(AND(35>=21, 35<21+UsefulLife), W2/UsefulLife, 0) -> 0
A26: Batch Nov-26 | B26: =IF(AND(0>=22, 0<22+UsefulLife), X2/UsefulLife, 0) -> 0 | C26: =IF(AND(1>=22, 1<22+UsefulLife), X2/UsefulLife, 0) -> 0 | D26: =IF(AND(2>=22, 2<22+UsefulLife), X2/UsefulLife, 0) -> 0 | E26: =IF(AND(3>=22, 3<22+UsefulLife), X2/UsefulLife, 0) -> 0 | F26: =IF(AND(4>=22, 4<22+UsefulLife), X2/UsefulLife, 0) -> 0 | G26: =IF(AND(5>=22, 5<22+UsefulLife), X2/UsefulLife, 0) -> 0 | H26: =IF(AND(6>=22, 6<22+UsefulLife), X2/UsefulLife, 0) -> 0 | I26: =IF(AND(7>=22, 7<22+UsefulLife), X2/UsefulLife, 0) -> 0 | J26: =IF(AND(8>=22, 8<22+UsefulLife), X2/UsefulLife, 0) -> 0 | K26: =IF(AND(9>=22, 9<22+UsefulLife), X2/UsefulLife, 0) -> 0 | L26: =IF(AND(10>=22, 10<22+UsefulLife), X2/UsefulLife, 0) -> 0 | M26: =IF(AND(11>=22, 11<22+UsefulLife), X2/UsefulLife, 0) -> 0 | N26: =IF(AND(12>=22, 12<22+UsefulLife), X2/UsefulLife, 0) -> 0 | O26: =IF(AND(13>=22, 13<22+UsefulLife), X2/UsefulLife, 0) -> 0 | P26: =IF(AND(14>=22, 14<22+UsefulLife), X2/UsefulLife, 0) -> 0 | Q26: =IF(AND(15>=22, 15<22+UsefulLife), X2/UsefulLife, 0) -> 0 | R26: =IF(AND(16>=22, 16<22+UsefulLife), X2/UsefulLife, 0) -> 0 | S26: =IF(AND(17>=22, 17<22+UsefulLife), X2/UsefulLife, 0) -> 0 | T26: =IF(AND(18>=22, 18<22+UsefulLife), X2/UsefulLife, 0) -> 0 | U26: =IF(AND(19>=22, 19<22+UsefulLife), X2/UsefulLife, 0) -> 0 | V26: =IF(AND(20>=22, 20<22+UsefulLife), X2/UsefulLife, 0) -> 0 | W26: =IF(AND(21>=22, 21<22+UsefulLife), X2/UsefulLife, 0) -> 0 | X26: =IF(AND(22>=22, 22<22+UsefulLife), X2/UsefulLife, 0) -> 0 | Y26: =IF(AND(23>=22, 23<22+UsefulLife), X2/UsefulLife, 0) -> 0 | Z26: =IF(AND(24>=22, 24<22+UsefulLife), X2/UsefulLife, 0) -> 0 | AA26: =IF(AND(25>=22, 25<22+UsefulLife), X2/UsefulLife, 0) -> 0 | AB26: =IF(AND(26>=22, 26<22+UsefulLife), X2/UsefulLife, 0) -> 0 | AC26: =IF(AND(27>=22, 27<22+UsefulLife), X2/UsefulLife, 0) -> 0 | AD26: =IF(AND(28>=22, 28<22+UsefulLife), X2/UsefulLife, 0) -> 0 | AE26: =IF(AND(29>=22, 29<22+UsefulLife), X2/UsefulLife, 0) -> 0 | AF26: =IF(AND(30>=22, 30<22+UsefulLife), X2/UsefulLife, 0) -> 0 | AG26: =IF(AND(31>=22, 31<22+UsefulLife), X2/UsefulLife, 0) -> 0 | AH26: =IF(AND(32>=22, 32<22+UsefulLife), X2/UsefulLife, 0) -> 0 | AI26: =IF(AND(33>=22, 33<22+UsefulLife), X2/UsefulLife, 0) -> 0 | AJ26: =IF(AND(34>=22, 34<22+UsefulLife), X2/UsefulLife, 0) -> 0 | AK26: =IF(AND(35>=22, 35<22+UsefulLife), X2/UsefulLife, 0) -> 0
A27: Batch Dec-26 | B27: =IF(AND(0>=23, 0<23+UsefulLife), Y2/UsefulLife, 0) -> 0 | C27: =IF(AND(1>=23, 1<23+UsefulLife), Y2/UsefulLife, 0) -> 0 | D27: =IF(AND(2>=23, 2<23+UsefulLife), Y2/UsefulLife, 0) -> 0 | E27: =IF(AND(3>=23, 3<23+UsefulLife), Y2/UsefulLife, 0) -> 0 | F27: =IF(AND(4>=23, 4<23+UsefulLife), Y2/UsefulLife, 0) -> 0 | G27: =IF(AND(5>=23, 5<23+UsefulLife), Y2/UsefulLife, 0) -> 0 | H27: =IF(AND(6>=23, 6<23+UsefulLife), Y2/UsefulLife, 0) -> 0 | I27: =IF(AND(7>=23, 7<23+UsefulLife), Y2/UsefulLife, 0) -> 0 | J27: =IF(AND(8>=23, 8<23+UsefulLife), Y2/UsefulLife, 0) -> 0 | K27: =IF(AND(9>=23, 9<23+UsefulLife), Y2/UsefulLife, 0) -> 0 | L27: =IF(AND(10>=23, 10<23+UsefulLife), Y2/UsefulLife, 0) -> 0 | M27: =IF(AND(11>=23, 11<23+UsefulLife), Y2/UsefulLife, 0) -> 0 | N27: =IF(AND(12>=23, 12<23+UsefulLife), Y2/UsefulLife, 0) -> 0 | O27: =IF(AND(13>=23, 13<23+UsefulLife), Y2/UsefulLife, 0) -> 0 | P27: =IF(AND(14>=23, 14<23+UsefulLife), Y2/UsefulLife, 0) -> 0 | Q27: =IF(AND(15>=23, 15<23+UsefulLife), Y2/UsefulLife, 0) -> 0 | R27: =IF(AND(16>=23, 16<23+UsefulLife), Y2/UsefulLife, 0) -> 0 | S27: =IF(AND(17>=23, 17<23+UsefulLife), Y2/UsefulLife, 0) -> 0 | T27: =IF(AND(18>=23, 18<23+UsefulLife), Y2/UsefulLife, 0) -> 0 | U27: =IF(AND(19>=23, 19<23+UsefulLife), Y2/UsefulLife, 0) -> 0 | V27: =IF(AND(20>=23, 20<23+UsefulLife), Y2/UsefulLife, 0) -> 0 | W27: =IF(AND(21>=23, 21<23+UsefulLife), Y2/UsefulLife, 0) -> 0 | X27: =IF(AND(22>=23, 22<23+UsefulLife), Y2/UsefulLife, 0) -> 0 | Y27: =IF(AND(23>=23, 23<23+UsefulLife), Y2/UsefulLife, 0) -> 0 | Z27: =IF(AND(24>=23, 24<23+UsefulLife), Y2/UsefulLife, 0) -> 0 | AA27: =IF(AND(25>=23, 25<23+UsefulLife), Y2/UsefulLife, 0) -> 0 | AB27: =IF(AND(26>=23, 26<23+UsefulLife), Y2/UsefulLife, 0) -> 0 | AC27: =IF(AND(27>=23, 27<23+UsefulLife), Y2/UsefulLife, 0) -> 0 | AD27: =IF(AND(28>=23, 28<23+UsefulLife), Y2/UsefulLife, 0) -> 0 | AE27: =IF(AND(29>=23, 29<23+UsefulLife), Y2/UsefulLife, 0) -> 0 | AF27: =IF(AND(30>=23, 30<23+UsefulLife), Y2/UsefulLife, 0) -> 0 | AG27: =IF(AND(31>=23, 31<23+UsefulLife), Y2/UsefulLife, 0) -> 0 | AH27: =IF(AND(32>=23, 32<23+UsefulLife), Y2/UsefulLife, 0) -> 0 | AI27: =IF(AND(33>=23, 33<23+UsefulLife), Y2/UsefulLife, 0) -> 0 | AJ27: =IF(AND(34>=23, 34<23+UsefulLife), Y2/UsefulLife, 0) -> 0 | AK27: =IF(AND(35>=23, 35<23+UsefulLife), Y2/UsefulLife, 0) -> 0
